#VRML_SIM R2021a utf8
WorldInfo {
  coordinateSystem "NUE"
}
Viewpoint {
  orientation -0.2502553827759296 0.9352548038381302 0.25034115780145616 1.613412031407163
  position 2.508273333120465 1.9315626407911484 0.06360733796756712
}
TexturedBackground {
}
TexturedBackgroundLight {
}
RectangleArena {
}
DEF ROBOT Robot {
  translation 2.4523575354246595e-09 0.03948106106855963 3.498304047420646e-14
  rotation -2.235874932652514e-07 8.390431483289775e-09 -0.999999999999975 6.130316134658724e-08
  children [
    DEF HINGE_COVER Solid {
      translation 0 0.03 -3.469446951953614e-18
      children [
        Shape {
          appearance PBRAppearance {
            baseColor 0 0.6509803921568628 1
          }
          geometry Box {
            size 0.030000000000000002 0.019999999999999997 0.05
          }
        }
      ]
      name "hingeCover"
    }
    DEF BODY Shape {
      appearance PBRAppearance {
        baseColor 0.917647 0.145098 0.145098
        roughness 1
        metalness 0
      }
      geometry Box {
        size 0.1 0.05 0.2
      }
    }
    DEF WHEEL1 HingeJoint {
      jointParameters HingeJointParameters {
        position 5.8112071004251145e-12
        anchor 0.06 0 0.05
      }
      device [
        RotationalMotor {
          name "wheel1"
        }
      ]
      endPoint Solid {
        translation 0.06 0 0.05
        rotation 2.9056003983608228e-12 -2.9056115505703688e-12 1 1.5708000000006916
        children [
          DEF WHEEL Shape {
            appearance PBRAppearance {
              baseColor 0.305882 0.898039 0.25098
              roughness 1
              metalness 0
            }
            geometry Cylinder {
              height 0.02
              radius 0.04
              subdivision 24
            }
          }
        ]
        boundingObject USE WHEEL
        physics Physics {
        }
        linearVelocity 1.8050771865702935e-11 -1.8056609390520366e-06 2.2947505943967755e-12
        angularVelocity 5.738257003976302e-11 -2.181864928573663e-15 -4.51243743953406e-10
      }
    }
    DEF WHEEL2 HingeJoint {
      jointParameters HingeJointParameters {
        position 5.81234742647931e-12
        anchor -0.06 0 0.05
      }
      device [
        RotationalMotor {
          name "wheel2"
        }
      ]
      endPoint Solid {
        translation -0.06 0 0.05
        rotation 2.9061791828117955e-12 -2.906190359198441e-12 1 1.5708000000006936
        children [
          USE WHEEL
        ]
        name "solid(1)"
        boundingObject USE WHEEL
        physics Physics {
        }
        linearVelocity 1.8050802811142682e-11 -1.8056078594298956e-06 2.2948204381450688e-12
        angularVelocity 5.7386832883595805e-11 -2.184495804215009e-15 -4.512513895176768e-10
      }
    }
    DEF WHEEL3 HingeJoint {
      jointParameters HingeJointParameters {
        position 5.811771681714125e-12
        anchor 0.06 0 -0.05
      }
      device [
        RotationalMotor {
          name "wheel3"
        }
      ]
      endPoint Solid {
        translation 0.06 0 -0.05
        rotation 2.9059193021862026e-12 -2.9059304715720676e-12 1 1.5708000000006943
        children [
          USE WHEEL
        ]
        name "solid(2)"
        boundingObject USE WHEEL
        physics Physics {
        }
        linearVelocity 1.8050642878933527e-11 -1.805661023234948e-06 2.2948837666261443e-12
        angularVelocity 5.7387581958680236e-11 -2.180852684923842e-15 -4.5124374395365666e-10
      }
    }
    DEF WHEEL4 HingeJoint {
      jointParameters HingeJointParameters {
        position 5.805973180405191e-12
        anchor -0.06 0 -0.05
      }
      device [
        RotationalMotor {
          name "wheel4"
        }
      ]
      endPoint Solid {
        translation -0.06 0 -0.05
        rotation 2.902917946557954e-12 -2.9029287717090435e-12 1 1.5708000000006928
        children [
          USE WHEEL
        ]
        name "solid(3)"
        boundingObject USE WHEEL
        physics Physics {
        }
        linearVelocity 1.805025972933184e-11 -1.805607941753196e-06 2.2932910305722335e-12
        angularVelocity 5.733057770088142e-11 -2.1870533766673807e-15 -4.5122335578253537e-10
      }
    }
    DEF POLE HingeJoint {
      jointParameters HingeJointParameters {
        position 1.4031300099115549e-13
        anchor 0 0.03000000000047226 0
        minStop -1.3
        maxStop 1.3
      }
      device [
        DEF POLE_POS_SENSOR PositionSensor {
          name "polePosSensor"
        }
      ]
      endPoint Solid {
        translation -1.8379558561220528e-06 0.5299968874104791 6.982837274995707e-14
        rotation 6.979767727552711e-14 -6.980909939689227e-14 1 1.5708000033841338
        children [
          DEF POLE_ENDPOINT Solid {
            translation 0.5000000000000002 0 0
            scale 0.1 0.1 0.1
            children [
              DEF BALL Shape {
                appearance PBRAppearance {
                  baseColor 0.03137254901960784 0.047058823529411764 1
                  metalness 0
                }
                geometry Sphere {
                  radius 0.1
                }
              }
            ]
            boundingObject USE BALL
            physics Physics {
              density -1
              mass 0.02
            }
          }
          DEF POLE Shape {
            appearance PBRAppearance {
              baseColor 1 0.1568627450980392 0.1568627450980392
              roughness 1
              metalness 0
            }
            geometry Box {
              size 1 0.020000000000000004 0.019999999999999997
            }
          }
        ]
        name "pole"
        boundingObject USE POLE
        physics Physics {
          density -1
          mass 0.2
        }
        linearVelocity 2.571611751731223e-10 -1.850509797565728e-06 9.018755337869195e-13
        angularVelocity -2.732059172880476e-12 -2.1774912299029965e-15 -4.5117208739177443e-10
      }
    }
  ]
  boundingObject USE BODY
  physics Physics {
    density -1
    mass 2
  }
  controller "robot_supervisor_manager_Stable_Baselines"
  supervisor TRUE
  linearVelocity 1.8040990475863522e-11 -1.8385430033078466e-06 2.2936147767733067e-12
  angularVelocity -8.50895824365113e-13 -2.177305430001263e-15 -4.511996110061689e-10
}
