#VRML_SIM R2022a utf8
WorldInfo {
  coordinateSystem "NUE"
}
Viewpoint {
  orientation 0.796017226768089 -0.5836543996278021 -0.16032503386418095 4.169459355131641
  position -2.735019547750672 3.7377231540207183 4.454693033958413
}
TexturedBackground {
}
TexturedBackgroundLight {
}
RectangleArena {
  rotation -0.5773484629300635 0.5773511723172876 0.5773511723172877 2.094397811784658
  floorSize 3.4 3.4
  floorTileSize 0.4 0.4
  floorAppearance Parquetry {
  }
  wallThickness 0.2
  wallHeight 0.2
}
DEF SUPERVISOR Robot {
  children [
    Receiver {
      rotation -0.5773502691896258 -0.5773502691896258 -0.5773502691896258 2.0943951023931953
      name "receiver8"
      channel 8
    }
    Emitter {
      rotation -0.5773502691896258 -0.5773502691896258 -0.5773502691896258 2.0943951023931953
      name "emitter8"
      channel 8
    }
    Receiver {
      rotation -0.5773502691896258 -0.5773502691896258 -0.5773502691896258 2.0943951023931953
      name "receiver7"
      channel 7
    }
    Emitter {
      rotation -0.5773502691896258 -0.5773502691896258 -0.5773502691896258 2.0943951023931953
      name "emitter7"
      channel 7
    }
    Receiver {
      rotation -0.5773502691896258 -0.5773502691896258 -0.5773502691896258 2.0943951023931953
      name "receiver6"
      channel 6
    }
    Emitter {
      rotation -0.5773502691896258 -0.5773502691896258 -0.5773502691896258 2.0943951023931953
      name "emitter6"
      channel 6
    }
    Receiver {
      rotation -0.5773502691896258 -0.5773502691896258 -0.5773502691896258 2.0943951023931953
      name "receiver5"
      channel 5
    }
    Emitter {
      rotation -0.5773502691896258 -0.5773502691896258 -0.5773502691896258 2.0943951023931953
      name "emitter5"
      channel 5
    }
    Receiver {
      rotation -0.5773502691896258 -0.5773502691896258 -0.5773502691896258 2.0943951023931953
      name "receiver4"
      channel 4
    }
    Emitter {
      rotation -0.5773502691896258 -0.5773502691896258 -0.5773502691896258 2.0943951023931953
      name "emitter4"
      channel 4
    }
    Receiver {
      rotation -0.5773502691896258 -0.5773502691896258 -0.5773502691896258 2.0943951023931953
      name "receiver3"
      channel 3
    }
    Emitter {
      rotation -0.5773502691896258 -0.5773502691896258 -0.5773502691896258 2.0943951023931953
      name "emitter3"
      channel 3
    }
    Receiver {
      rotation -0.5773502691896258 -0.5773502691896258 -0.5773502691896258 2.0943951023931953
      name "receiver2"
      channel 2
    }
    Emitter {
      rotation -0.5773502691896258 -0.5773502691896258 -0.5773502691896258 2.0943951023931953
      name "emitter2"
      channel 2
    }
    Receiver {
      rotation -0.5773502691896258 -0.5773502691896258 -0.5773502691896258 2.0943951023931953
      name "receiver1"
      channel 1
    }
    Emitter {
      rotation -0.5773502691896258 -0.5773502691896258 -0.5773502691896258 2.0943951023931953
      name "emitter1"
      channel 1
    }
    Receiver {
      rotation -0.5773502691896258 -0.5773502691896258 -0.5773502691896258 2.0943951023931953
      name "receiver0"
    }
    Emitter {
      rotation -0.5773502691896258 -0.5773502691896258 -0.5773502691896258 2.0943951023931953
      name "emitter0"
    }
  ]
  name "supervisor"
  controller "supervisor_manager"
  supervisor TRUE
}
DEF Boundary_Boxes Group {
  children [
    SolidBox {
      translation 0.8 0.1 0.6
      rotation -0.5773502691896258 0.5773502691896258 0.5773502691896258 2.0943951023931953
      name "box(24)"
      size 0.2 0.2 0.2
    }
    SolidBox {
      translation 1 0.1 0.6
      rotation -0.5773502691896258 0.5773502691896258 0.5773502691896258 2.0943951023931953
      name "box(23)"
      size 0.2 0.2 0.2
    }
    SolidBox {
      translation 1.4 0.1 0.6
      rotation -0.5773502691896258 0.5773502691896258 0.5773502691896258 2.0943951023931953
      name "box(21)"
      size 0.2 0.2 0.2
    }
    SolidBox {
      translation 1.2 0.1 0.6
      rotation -0.5773502691896258 0.5773502691896258 0.5773502691896258 2.0943951023931953
      name "box(22)"
      size 0.2 0.2 0.2
    }
    SolidBox {
      translation 0.6 0.1 0.6
      rotation -0.5773502691896258 0.5773502691896258 0.5773502691896258 2.0943951023931953
      name "box(20)"
      size 0.2 0.2 0.2
    }
    SolidBox {
      translation 0.6 0.1 0.8
      rotation -0.5773502691896258 0.5773502691896258 0.5773502691896258 2.0943951023931953
      name "box(19)"
      size 0.2 0.2 0.2
    }
    SolidBox {
      translation 0.6 0.1 1
      rotation -0.5773502691896258 0.5773502691896258 0.5773502691896258 2.0943951023931953
      name "box(18)"
      size 0.2 0.2 0.2
    }
    SolidBox {
      translation 0.6 0.1 1.2
      rotation -0.5773502691896258 0.5773502691896258 0.5773502691896258 2.0943951023931953
      name "box(17)"
      size 0.2 0.2 0.2
    }
    SolidBox {
      translation 0.6 0.1 1.4
      rotation -0.5773502691896258 0.5773502691896258 0.5773502691896258 2.0943951023931953
      name "box(16)"
      size 0.2 0.2 0.2
    }
    SolidBox {
      translation 0.6 0.1 1.6
      rotation -0.5773502691896258 0.5773502691896258 0.5773502691896258 2.0943951023931953
      name "box(15)"
      size 0.2 0.2 0.2
    }
    SolidBox {
      translation 0.4 0.1 0.6
      rotation -0.5773502691896258 0.5773502691896258 0.5773502691896258 2.0943951023931953
      name "box(74)"
      size 0.2 0.2 0.2
    }
    SolidBox {
      translation 0.2 0.1 0.6
      rotation -0.5773502691896258 0.5773502691896258 0.5773502691896258 2.0943951023931953
      name "box(73)"
      size 0.2 0.2 0.2
    }
    SolidBox {
      translation 0 0.1 0.6
      rotation -0.5773502691896258 0.5773502691896258 0.5773502691896258 2.0943951023931953
      name "box(72)"
      size 0.2 0.2 0.2
    }
    SolidBox {
      translation -0.2 0.1 0.6
      rotation -0.5773502691896258 0.5773502691896258 0.5773502691896258 2.0943951023931953
      name "box(71)"
      size 0.2 0.2 0.2
    }
    SolidBox {
      translation -0.4 0.1 0.6
      rotation -0.5773502691896258 0.5773502691896258 0.5773502691896258 2.0943951023931953
      name "box(70)"
      size 0.2 0.2 0.2
    }
    SolidBox {
      translation 0.4 0.1 -0.6
      rotation -0.5773502691896258 0.5773502691896258 0.5773502691896258 2.0943951023931953
      name "box(85)"
      size 0.2 0.2 0.2
    }
    SolidBox {
      translation 0.2 0.1 -0.6
      rotation -0.5773502691896258 0.5773502691896258 0.5773502691896258 2.0943951023931953
      name "box(84)"
      size 0.2 0.2 0.2
    }
    SolidBox {
      translation 0 0.1 -0.6
      rotation -0.5773502691896258 0.5773502691896258 0.5773502691896258 2.0943951023931953
      name "box(83)"
      size 0.2 0.2 0.2
    }
    SolidBox {
      translation -0.2 0.1 -0.6
      rotation -0.5773502691896258 0.5773502691896258 0.5773502691896258 2.0943951023931953
      name "box(82)"
      size 0.2 0.2 0.2
    }
    SolidBox {
      translation -0.4 0.1 -0.6
      rotation -0.5773502691896258 0.5773502691896258 0.5773502691896258 2.0943951023931953
      name "box(81)"
      size 0.2 0.2 0.2
    }
    SolidBox {
      translation -0.8 0.1 0.6
      rotation -0.5773502691896258 0.5773502691896258 0.5773502691896258 2.0943951023931953
      name "box(125)"
      size 0.2 0.2 0.2
    }
    SolidBox {
      translation -1 0.1 0.6
      rotation -0.5773502691896258 0.5773502691896258 0.5773502691896258 2.0943951023931953
      name "box(124)"
      size 0.2 0.2 0.2
    }
    SolidBox {
      translation -1.2 0.1 0.6
      rotation -0.5773502691896258 0.5773502691896258 0.5773502691896258 2.0943951023931953
      name "box(123)"
      size 0.2 0.2 0.2
    }
    SolidBox {
      translation -1.4 0.1 0.6
      rotation -0.5773502691896258 0.5773502691896258 0.5773502691896258 2.0943951023931953
      name "box(122)"
      size 0.2 0.2 0.2
    }
    SolidBox {
      translation -1.6 0.1 0.6
      rotation -0.5773502691896258 0.5773502691896258 0.5773502691896258 2.0943951023931953
      name "box(121)"
      size 0.2 0.2 0.2
    }
    SolidBox {
      translation -0.8 0.1 -0.6
      rotation -0.5773502691896258 0.5773502691896258 0.5773502691896258 2.0943951023931953
      name "box(114)"
      size 0.2 0.2 0.2
    }
    SolidBox {
      translation -1 0.1 -0.6
      rotation -0.5773502691896258 0.5773502691896258 0.5773502691896258 2.0943951023931953
      name "box(113)"
      size 0.2 0.2 0.2
    }
    SolidBox {
      translation -1.2 0.1 -0.6
      rotation -0.5773502691896258 0.5773502691896258 0.5773502691896258 2.0943951023931953
      name "box(112)"
      size 0.2 0.2 0.2
    }
    SolidBox {
      translation -1.4 0.1 -0.6
      rotation -0.5773502691896258 0.5773502691896258 0.5773502691896258 2.0943951023931953
      name "box(111)"
      size 0.2 0.2 0.2
    }
    SolidBox {
      translation -1.6 0.1 -0.6
      rotation -0.5773502691896258 0.5773502691896258 0.5773502691896258 2.0943951023931953
      name "box(109)"
      size 0.2 0.2 0.2
    }
    SolidBox {
      translation -0.6 0.1 -1.6
      rotation -0.5773502691896258 0.5773502691896258 0.5773502691896258 2.0943951023931953
      name "box(90)"
      size 0.2 0.2 0.2
    }
    SolidBox {
      translation -0.6 0.1 -1.4
      rotation -0.5773502691896258 0.5773502691896258 0.5773502691896258 2.0943951023931953
      name "box(89)"
      size 0.2 0.2 0.2
    }
    SolidBox {
      translation -0.6 0.1 -1.2
      rotation -0.5773502691896258 0.5773502691896258 0.5773502691896258 2.0943951023931953
      name "box(88)"
      size 0.2 0.2 0.2
    }
    SolidBox {
      translation -0.6 0.1 -1
      rotation -0.5773502691896258 0.5773502691896258 0.5773502691896258 2.0943951023931953
      name "box(87)"
      size 0.2 0.2 0.2
    }
    SolidBox {
      translation -0.6 0.1 -0.8
      rotation -0.5773502691896258 0.5773502691896258 0.5773502691896258 2.0943951023931953
      name "box(86)"
      size 0.2 0.2 0.2
    }
    SolidBox {
      translation -0.6 0.1 -0.6
      rotation -0.5773502691896258 0.5773502691896258 0.5773502691896258 2.0943951023931953
      name "box(80)"
      size 0.2 0.2 0.2
    }
    SolidBox {
      translation -0.6 0.1 -0.4
      rotation -0.5773502691896258 0.5773502691896258 0.5773502691896258 2.0943951023931953
      name "box(79)"
      size 0.2 0.2 0.2
    }
    SolidBox {
      translation -0.6 0.1 -0.2
      rotation -0.5773502691896258 0.5773502691896258 0.5773502691896258 2.0943951023931953
      name "box(78)"
      size 0.2 0.2 0.2
    }
    SolidBox {
      translation -0.6 0.1 0
      rotation -0.5773502691896258 0.5773502691896258 0.5773502691896258 2.0943951023931953
      name "box(77)"
      size 0.2 0.2 0.2
    }
    SolidBox {
      translation -0.6 0.1 0.2
      rotation -0.5773502691896258 0.5773502691896258 0.5773502691896258 2.0943951023931953
      name "box(76)"
      size 0.2 0.2 0.2
    }
    SolidBox {
      translation -0.6 0.1 0.4
      rotation -0.5773502691896258 0.5773502691896258 0.5773502691896258 2.0943951023931953
      name "box(75)"
      size 0.2 0.2 0.2
    }
    SolidBox {
      translation -0.6 0.1 0.6
      rotation -0.5773502691896258 0.5773502691896258 0.5773502691896258 2.0943951023931953
      name "box(69)"
      size 0.2 0.2 0.2
    }
    SolidBox {
      translation -0.6 0.1 0.8
      rotation -0.5773502691896258 0.5773502691896258 0.5773502691896258 2.0943951023931953
      name "box(68)"
      size 0.2 0.2 0.2
    }
    SolidBox {
      translation -0.6 0.1 1
      rotation -0.5773502691896258 0.5773502691896258 0.5773502691896258 2.0943951023931953
      name "box(67)"
      size 0.2 0.2 0.2
    }
    SolidBox {
      translation -0.6 0.1 1.2
      rotation -0.5773502691896258 0.5773502691896258 0.5773502691896258 2.0943951023931953
      name "box(66)"
      size 0.2 0.2 0.2
    }
    SolidBox {
      translation -0.6 0.1 1.4
      rotation -0.5773502691896258 0.5773502691896258 0.5773502691896258 2.0943951023931953
      name "box(65)"
      size 0.2 0.2 0.2
    }
    SolidBox {
      translation -0.6 0.1 1.6
      rotation -0.5773502691896258 0.5773502691896258 0.5773502691896258 2.0943951023931953
      name "box(64)"
      size 0.2 0.2 0.2
    }
    SolidBox {
      translation 1.6 0.1 0.6
      rotation -0.5773502691896258 0.5773502691896258 0.5773502691896258 2.0943951023931953
      name "box(12)"
      size 0.2 0.2 0.2
    }
    SolidBox {
      translation 0.6 0.1 0.4
      rotation -0.5773502691896258 0.5773502691896258 0.5773502691896258 2.0943951023931953
      name "box(40)"
      size 0.2 0.2 0.2
    }
    SolidBox {
      translation 0.6 0.1 0.2
      rotation -0.5773502691896258 0.5773502691896258 0.5773502691896258 2.0943951023931953
      name "box(39)"
      size 0.2 0.2 0.2
    }
    SolidBox {
      translation 0.6 0.1 0
      rotation -0.5773502691896258 0.5773502691896258 0.5773502691896258 2.0943951023931953
      name "box(38)"
      size 0.2 0.2 0.2
    }
    SolidBox {
      translation 0.6 0.1 -0.2
      rotation -0.5773502691896258 0.5773502691896258 0.5773502691896258 2.0943951023931953
      name "box(37)"
      size 0.2 0.2 0.2
    }
    SolidBox {
      translation 0.6 0.1 -0.4
      rotation -0.5773502691896258 0.5773502691896258 0.5773502691896258 2.0943951023931953
      name "box(36)"
      size 0.2 0.2 0.2
    }
    SolidBox {
      translation 0.6 0.1 -1.6
      rotation -0.5773502691896258 0.5773502691896258 0.5773502691896258 2.0943951023931953
      name "box(45)"
      size 0.2 0.2 0.2
    }
    SolidBox {
      translation 0.6 0.1 -1.4
      rotation -0.5773502691896258 0.5773502691896258 0.5773502691896258 2.0943951023931953
      name "box(44)"
      size 0.2 0.2 0.2
    }
    SolidBox {
      translation 0.6 0.1 -1.2
      rotation -0.5773502691896258 0.5773502691896258 0.5773502691896258 2.0943951023931953
      name "box(43)"
      size 0.2 0.2 0.2
    }
    SolidBox {
      translation 0.6 0.1 -1
      rotation -0.5773502691896258 0.5773502691896258 0.5773502691896258 2.0943951023931953
      name "box(42)"
      size 0.2 0.2 0.2
    }
    SolidBox {
      translation 0.6 0.1 -0.8
      rotation -0.5773502691896258 0.5773502691896258 0.5773502691896258 2.0943951023931953
      name "box(41)"
      size 0.2 0.2 0.2
    }
    SolidBox {
      translation 0.6 0.1 -0.6
      rotation -0.5773502691896258 0.5773502691896258 0.5773502691896258 2.0943951023931953
      name "box(35)"
      size 0.2 0.2 0.2
    }
    SolidBox {
      translation 0.8 0.1 -0.6
      rotation -0.5773502691896258 0.5773502691896258 0.5773502691896258 2.0943951023931953
      name "box(34)"
      size 0.2 0.2 0.2
    }
    SolidBox {
      translation 1 0.1 -0.6
      rotation -0.5773502691896258 0.5773502691896258 0.5773502691896258 2.0943951023931953
      name "box(33)"
      size 0.2 0.2 0.2
    }
    SolidBox {
      translation 1.2 0.1 -0.6
      rotation -0.5773502691896258 0.5773502691896258 0.5773502691896258 2.0943951023931953
      name "box(32)"
      size 0.2 0.2 0.2
    }
    SolidBox {
      translation 1.4 0.1 -0.6
      rotation -0.5773502691896258 0.5773502691896258 0.5773502691896258 2.0943951023931953
      name "box(31)"
      size 0.2 0.2 0.2
    }
    SolidBox {
      translation 1.6 0.1 -0.6
      rotation -0.5773502691896258 0.5773502691896258 0.5773502691896258 2.0943951023931953
      name "box(30)"
      size 0.2 0.2 0.2
    }
  ]
}
DEF ROBOT2 Robot {
  translation 1.2 0.04 -1.2
  rotation 0 0 -0.9999999999999978 0
  children [
    Receiver {
      channel 2
    }
    Emitter {
      channel 2
    }
    DEF HINGE_COVER Solid {
      translation 0 0.03 -3.469446951953614e-18
      children [
        Shape {
          appearance PBRAppearance {
            baseColor 0 0.6509803921568628 1
          }
          geometry Box {
            size 0.030000000000000002 0.019999999999999997 0.05
          }
        }
      ]
      name "hingeCover"
    }
    DEF BODY Shape {
      appearance PBRAppearance {
        baseColor 0.917647 0.145098 0.145098
        roughness 1
        metalness 0
      }
      geometry Box {
        size 0.1 0.05 0.2
      }
    }
    DEF WHEEL1 HingeJoint {
      jointParameters HingeJointParameters {
        position 6.723540149111039e-17
        anchor 0.06 0 0.05
      }
      device [
        RotationalMotor {
          name "wheel1"
        }
      ]
      endPoint Solid {
        translation 0.06 0 0.05
        rotation -0.5773489358957503 -0.5773509357752342 0.5773509358955837 2.0943953072989028
        children [
          DEF WHEEL Shape {
            appearance PBRAppearance {
              baseColor 0.305882 0.898039 0.25098
              roughness 1
              metalness 0
            }
            geometry Cylinder {
              height 0.02
              radius 0.04
              subdivision 24
            }
          }
        ]
        boundingObject USE WHEEL
        physics Physics {
        }
      }
    }
    DEF WHEEL2 HingeJoint {
      jointParameters HingeJointParameters {
        position 6.670640318240083e-17
        anchor -0.06 0 0.05
      }
      device [
        RotationalMotor {
          name "wheel2"
        }
      ]
      endPoint Solid {
        translation -0.06 0 0.05
        rotation -0.5773489359475542 -0.5773509356716215 0.5773509359473926 2.094395307454274
        children [
          USE WHEEL
        ]
        name "solid(1)"
        boundingObject USE WHEEL
        physics Physics {
        }
      }
    }
    DEF WHEEL3 HingeJoint {
      jointParameters HingeJointParameters {
        position 1.0324509589061627e-16
        anchor 0.06 0 -0.05
      }
      device [
        RotationalMotor {
          name "wheel3"
        }
      ]
      endPoint Solid {
        translation 0.06 0 -0.05
        rotation 0.5773509359565014 0.5773499356553075 0.577349935956491 2.0943900003001836
        children [
          USE WHEEL
        ]
        name "solid(2)"
        boundingObject USE WHEEL
        physics Physics {
        }
      }
    }
    DEF WHEEL4 HingeJoint {
      jointParameters HingeJointParameters {
        position -2.6895122773572173e-17
        anchor -0.06 0 -0.05
      }
      device [
        RotationalMotor {
          name "wheel4"
        }
      ]
      endPoint Solid {
        translation -0.06 0 -0.05
        rotation -0.5773489357502593 -0.5773509360661835 0.5773509357501247 2.09439530686173
        children [
          USE WHEEL
        ]
        name "solid(3)"
        boundingObject USE WHEEL
        physics Physics {
        }
      }
    }
    DEF POLE HingeJoint {
      jointParameters HingeJointParameters {
        position -4.812689688184746e-16
        anchor 0 0.03000000000047226 0
        minStop -1.3
        maxStop 1.3
      }
      device [
        DEF POLE_POS_SENSOR_2 PositionSensor {
          name "polePosSensor"
        }
      ]
      endPoint Solid {
        translation -1.8379558561206763e-06 0.5299968874105057 -1.1687285415657023e-10
        rotation -1.1685117900947696e-10 1.1687645745336203e-10 1 1.570800003382605
        children [
          DEF POLE_ENDPOINT_2 Solid {
            translation 0.5000000000000002 0 0
            scale 0.1 0.1 0.1
            children [
              DEF BALL Shape {
                appearance PBRAppearance {
                  baseColor 0.03137254901960784 0.047058823529411764 1
                  metalness 0
                }
                geometry Sphere {
                  radius 0.1
                }
              }
            ]
            boundingObject USE BALL
            physics Physics {
              density -1
              mass 0.02
            }
          }
          DEF POLE Shape {
            appearance PBRAppearance {
              baseColor 1 0.1568627450980392 0.1568627450980392
              roughness 1
              metalness 0
            }
            geometry Box {
              size 1 0.020000000000000004 0.019999999999999997
            }
          }
        ]
        name "pole"
        boundingObject USE POLE
        physics Physics {
          density -1
          mass 0.2
        }
      }
    }
  ]
  name "robot2"
  boundingObject USE BODY
  physics Physics {
    density -1
    mass 2
  }
  controller "robot_controller"
  supervisor TRUE
}
DEF ROBOT1 Robot {
  translation 0 0.04 -1.2
  rotation 0 0 -0.9999999999999978 0
  children [
    Receiver {
      channel 1
    }
    Emitter {
      channel 1
    }
    DEF HINGE_COVER Solid {
      translation 0 0.03 -3.469446951953614e-18
      children [
        Shape {
          appearance PBRAppearance {
            baseColor 0 0.6509803921568628 1
          }
          geometry Box {
            size 0.030000000000000002 0.019999999999999997 0.05
          }
        }
      ]
      name "hingeCover"
    }
    DEF BODY Shape {
      appearance PBRAppearance {
        baseColor 0.917647 0.145098 0.145098
        roughness 1
        metalness 0
      }
      geometry Box {
        size 0.1 0.05 0.2
      }
    }
    DEF WHEEL1 HingeJoint {
      jointParameters HingeJointParameters {
        position 6.723540149111039e-17
        anchor 0.06 0 0.05
      }
      device [
        RotationalMotor {
          name "wheel1"
        }
      ]
      endPoint Solid {
        translation 0.06 0 0.05
        rotation -0.5773489356538368 -0.5773509362589924 0.5773509356537382 2.094395306572866
        children [
          DEF WHEEL Shape {
            appearance PBRAppearance {
              baseColor 0.305882 0.898039 0.25098
              roughness 1
              metalness 0
            }
            geometry Cylinder {
              height 0.02
              radius 0.04
              subdivision 24
            }
          }
        ]
        boundingObject USE WHEEL
        physics Physics {
        }
      }
    }
    DEF WHEEL2 HingeJoint {
      jointParameters HingeJointParameters {
        position 6.670640318240083e-17
        anchor -0.06 0 0.05
      }
      device [
        RotationalMotor {
          name "wheel2"
        }
      ]
      endPoint Solid {
        translation -0.06 0 0.05
        rotation -0.5773489357147059 -0.5773509361372791 0.5773509357145824 2.0943953067552226
        children [
          USE WHEEL
        ]
        name "solid(1)"
        boundingObject USE WHEEL
        physics Physics {
        }
      }
    }
    DEF WHEEL3 HingeJoint {
      jointParameters HingeJointParameters {
        position 1.0324509589061627e-16
        anchor 0.06 0 -0.05
      }
      device [
        RotationalMotor {
          name "wheel3"
        }
      ]
      endPoint Solid {
        translation 0.06 0 -0.05
        rotation 0.5773509358080592 0.5773499359521561 0.5773499358080849 2.0943899998553137
        children [
          USE WHEEL
        ]
        name "solid(2)"
        boundingObject USE WHEEL
        physics Physics {
        }
      }
    }
    DEF WHEEL4 HingeJoint {
      jointParameters HingeJointParameters {
        position -2.6895122773572173e-17
        anchor -0.06 0 -0.05
      }
      device [
        RotationalMotor {
          name "wheel4"
        }
      ]
      endPoint Solid {
        translation -0.06 0 -0.05
        rotation -0.5773489359135656 -0.5773509357396522 0.5773509359133501 2.0943953073523174
        children [
          USE WHEEL
        ]
        name "solid(3)"
        boundingObject USE WHEEL
        physics Physics {
        }
      }
    }
    DEF POLE HingeJoint {
      jointParameters HingeJointParameters {
        position -4.812689688184746e-16
        anchor 0 0.03000000000047226 0
        minStop -1.3
        maxStop 1.3
      }
      device [
        DEF POLE_POS_SENSOR_1 PositionSensor {
          name "polePosSensor"
        }
      ]
      endPoint Solid {
        translation -1.8379558561205501e-06 0.5299968874105183 -1.16830193836849e-10
        rotation -1.1682937439053972e-10 1.1682784355497608e-10 1 1.5708000033826142
        children [
          DEF POLE_ENDPOINT_1 Solid {
            translation 0.5000000000000002 0 0
            scale 0.1 0.1 0.1
            children [
              DEF BALL Shape {
                appearance PBRAppearance {
                  baseColor 0.03137254901960784 0.047058823529411764 1
                  metalness 0
                }
                geometry Sphere {
                  radius 0.1
                }
              }
            ]
            boundingObject USE BALL
            physics Physics {
              density -1
              mass 0.02
            }
          }
          DEF POLE Shape {
            appearance PBRAppearance {
              baseColor 1 0.1568627450980392 0.1568627450980392
              roughness 1
              metalness 0
            }
            geometry Box {
              size 1 0.020000000000000004 0.019999999999999997
            }
          }
        ]
        name "pole"
        boundingObject USE POLE
        physics Physics {
          density -1
          mass 0.2
        }
      }
    }
  ]
  name "robot1"
  boundingObject USE BODY
  physics Physics {
    density -1
    mass 2
  }
  controller "robot_controller"
  supervisor TRUE
}
DEF ROBOT3 Robot {
  translation -1.2 0.04 1.2
  rotation 0 0 -0.9999999999999978 0
  children [
    Receiver {
      channel 3
    }
    Emitter {
      channel 3
    }
    DEF HINGE_COVER Solid {
      translation 0 0.03 -3.469446951953614e-18
      children [
        Shape {
          appearance PBRAppearance {
            baseColor 0 0.6509803921568628 1
          }
          geometry Box {
            size 0.030000000000000002 0.019999999999999997 0.05
          }
        }
      ]
      name "hingeCover"
    }
    DEF BODY Shape {
      appearance PBRAppearance {
        baseColor 0.917647 0.145098 0.145098
        roughness 1
        metalness 0
      }
      geometry Box {
        size 0.1 0.05 0.2
      }
    }
    DEF WHEEL1 HingeJoint {
      jointParameters HingeJointParameters {
        position 6.723540149111039e-17
        anchor 0.06 0 0.05
      }
      device [
        RotationalMotor {
          name "wheel1"
        }
      ]
      endPoint Solid {
        translation 0.06 0 0.05
        rotation -0.5773489358410112 -0.577350935884728 0.5773509358408287 2.0943953071345587
        children [
          DEF WHEEL Shape {
            appearance PBRAppearance {
              baseColor 0.305882 0.898039 0.25098
              roughness 1
              metalness 0
            }
            geometry Cylinder {
              height 0.02
              radius 0.04
              subdivision 24
            }
          }
        ]
        boundingObject USE WHEEL
        physics Physics {
        }
      }
    }
    DEF WHEEL2 HingeJoint {
      jointParameters HingeJointParameters {
        position 6.670640318240083e-17
        anchor -0.06 0 0.05
      }
      device [
        RotationalMotor {
          name "wheel2"
        }
      ]
      endPoint Solid {
        translation -0.06 0 0.05
        rotation -0.5773489358718199 -0.5773509358230978 0.5773509358716501 2.0943953072269283
        children [
          USE WHEEL
        ]
        name "solid(1)"
        boundingObject USE WHEEL
        physics Physics {
        }
      }
    }
    DEF WHEEL3 HingeJoint {
      jointParameters HingeJointParameters {
        position 1.0324509589061627e-16
        anchor 0.06 0 -0.05
      }
      device [
        RotationalMotor {
          name "wheel3"
        }
      ]
      endPoint Solid {
        translation 0.06 0 -0.05
        rotation 0.5773509357947606 0.5773499359787718 0.5773499357947677 2.09438999981559
        children [
          USE WHEEL
        ]
        name "solid(2)"
        boundingObject USE WHEEL
        physics Physics {
        }
      }
    }
    DEF WHEEL4 HingeJoint {
      jointParameters HingeJointParameters {
        position -2.6895122773572173e-17
        anchor -0.06 0 -0.05
      }
      device [
        RotationalMotor {
          name "wheel4"
        }
      ]
      endPoint Solid {
        translation -0.06 0 -0.05
        rotation -0.5773489359188683 -0.5773509357289993 0.5773509359187006 2.0943953073681407
        children [
          USE WHEEL
        ]
        name "solid(3)"
        boundingObject USE WHEEL
        physics Physics {
        }
      }
    }
    DEF POLE HingeJoint {
      jointParameters HingeJointParameters {
        position -4.812689688184746e-16
        anchor 0 0.03000000000047226 0
        minStop -1.3
        maxStop 1.3
      }
      device [
        DEF POLE_POS_SENSOR_3 PositionSensor {
          name "polePosSensor"
        }
      ]
      endPoint Solid {
        translation -1.8379558561204582e-06 0.5299968874104672 -1.1678942089626965e-10
        rotation -1.1679292868634407e-10 1.1679661839860864e-10 1 1.5708000033825504
        children [
          DEF POLE_ENDPOINT_3 Solid {
            translation 0.5000000000000002 0 0
            scale 0.1 0.1 0.1
            children [
              DEF BALL Shape {
                appearance PBRAppearance {
                  baseColor 0.03137254901960784 0.047058823529411764 1
                  metalness 0
                }
                geometry Sphere {
                  radius 0.1
                }
              }
            ]
            boundingObject USE BALL
            physics Physics {
              density -1
              mass 0.02
            }
          }
          DEF POLE Shape {
            appearance PBRAppearance {
              baseColor 1 0.1568627450980392 0.1568627450980392
              roughness 1
              metalness 0
            }
            geometry Box {
              size 1 0.020000000000000004 0.019999999999999997
            }
          }
        ]
        name "pole"
        boundingObject USE POLE
        physics Physics {
          density -1
          mass 0.2
        }
      }
    }
  ]
  name "robot3"
  boundingObject USE BODY
  physics Physics {
    density -1
    mass 2
  }
  controller "robot_controller"
  supervisor TRUE
}
DEF ROBOT4 Robot {
  translation -1.2 0.04 0
  rotation 0 0 -0.9999999999999978 0
  children [
    Emitter {
      channel 4
    }
    Receiver {
      channel 4
    }
    DEF HINGE_COVER Solid {
      translation 0 0.03 -3.469446951953614e-18
      children [
        Shape {
          appearance PBRAppearance {
            baseColor 0 0.6509803921568628 1
          }
          geometry Box {
            size 0.030000000000000002 0.019999999999999997 0.05
          }
        }
      ]
      name "hingeCover"
    }
    DEF BODY Shape {
      appearance PBRAppearance {
        baseColor 0.917647 0.145098 0.145098
        roughness 1
        metalness 0
      }
      geometry Box {
        size 0.1 0.05 0.2
      }
    }
    DEF WHEEL1 HingeJoint {
      jointParameters HingeJointParameters {
        position 6.723540149111039e-17
        anchor 0.06 0 0.05
      }
      device [
        RotationalMotor {
          name "wheel1"
        }
      ]
      endPoint Solid {
        translation 0.06 0 0.05
        rotation -0.5773489358482844 -0.5773509358701931 0.5773509358480905 2.0943953071563315
        children [
          DEF WHEEL Shape {
            appearance PBRAppearance {
              baseColor 0.305882 0.898039 0.25098
              roughness 1
              metalness 0
            }
            geometry Cylinder {
              height 0.02
              radius 0.04
              subdivision 24
            }
          }
        ]
        boundingObject USE WHEEL
        physics Physics {
        }
      }
    }
    DEF WHEEL2 HingeJoint {
      jointParameters HingeJointParameters {
        position 6.670640318240083e-17
        anchor -0.06 0 0.05
      }
      device [
        RotationalMotor {
          name "wheel2"
        }
      ]
      endPoint Solid {
        translation -0.06 0 0.05
        rotation -0.5773489358603765 -0.5773509358460581 0.5773509358601333 2.0943953071924657
        children [
          USE WHEEL
        ]
        name "solid(1)"
        boundingObject USE WHEEL
        physics Physics {
        }
      }
    }
    DEF WHEEL3 HingeJoint {
      jointParameters HingeJointParameters {
        position 1.0324509589061627e-16
        anchor 0.06 0 -0.05
      }
      device [
        RotationalMotor {
          name "wheel3"
        }
      ]
      endPoint Solid {
        translation 0.06 0 -0.05
        rotation 0.5773509359848641 0.5773499355986028 0.5773499359848328 2.0943900003857014
        children [
          USE WHEEL
        ]
        name "solid(2)"
        boundingObject USE WHEEL
        physics Physics {
        }
      }
    }
    DEF WHEEL4 HingeJoint {
      jointParameters HingeJointParameters {
        position -2.6895122773572173e-17
        anchor -0.06 0 -0.05
      }
      device [
        RotationalMotor {
          name "wheel4"
        }
      ]
      endPoint Solid {
        translation -0.06 0 -0.05
        rotation -0.577348935726378 -0.5773509361138994 0.5773509357262899 2.0943953067903816
        children [
          USE WHEEL
        ]
        name "solid(3)"
        boundingObject USE WHEEL
        physics Physics {
        }
      }
    }
    DEF POLE HingeJoint {
      jointParameters HingeJointParameters {
        position -4.812689688184746e-16
        anchor 0 0.03000000000047226 0
        minStop -1.3
        maxStop 1.3
      }
      device [
        DEF POLE_POS_SENSOR_4 PositionSensor {
          name "polePosSensor"
        }
      ]
      endPoint Solid {
        translation -1.8379558561204722e-06 0.5299968874104697 -1.1658785990614895e-10
        rotation -1.1656852363420845e-10 1.1659327217286282e-10 1 1.5708000033825562
        children [
          DEF POLE_ENDPOINT_4 Solid {
            translation 0.5000000000000002 0 0
            scale 0.1 0.1 0.1
            children [
              DEF BALL Shape {
                appearance PBRAppearance {
                  baseColor 0.03137254901960784 0.047058823529411764 1
                  metalness 0
                }
                geometry Sphere {
                  radius 0.1
                }
              }
            ]
            boundingObject USE BALL
            physics Physics {
              density -1
              mass 0.02
            }
          }
          DEF POLE Shape {
            appearance PBRAppearance {
              baseColor 1 0.1568627450980392 0.1568627450980392
              roughness 1
              metalness 0
            }
            geometry Box {
              size 1 0.020000000000000004 0.019999999999999997
            }
          }
        ]
        name "pole"
        boundingObject USE POLE
        physics Physics {
          density -1
          mass 0.2
        }
      }
    }
  ]
  name "robot4"
  boundingObject USE BODY
  physics Physics {
    density -1
    mass 2
  }
  controller "robot_controller"
  supervisor TRUE
}
DEF ROBOT5 Robot {
  translation 0 0.04 0
  rotation 0 0 -0.9999999999999978 0
  children [
    Receiver {
      channel 5
    }
    Emitter {
      channel 5
    }
    DEF HINGE_COVER Solid {
      translation 0 0.03 -3.469446951953614e-18
      children [
        Shape {
          appearance PBRAppearance {
            baseColor 0 0.6509803921568628 1
          }
          geometry Box {
            size 0.030000000000000002 0.019999999999999997 0.05
          }
        }
      ]
      name "hingeCover"
    }
    DEF BODY Shape {
      appearance PBRAppearance {
        baseColor 0.917647 0.145098 0.145098
        roughness 1
        metalness 0
      }
      geometry Box {
        size 0.1 0.05 0.2
      }
    }
    DEF WHEEL1 HingeJoint {
      jointParameters HingeJointParameters {
        position 6.723540149111039e-17
        anchor 0.06 0 0.05
      }
      device [
        RotationalMotor {
          name "wheel1"
        }
      ]
      endPoint Solid {
        translation 0.06 0 0.05
        rotation -0.5773489356664184 -0.5773509362338112 0.5773509356663378 2.094395306610596
        children [
          DEF WHEEL Shape {
            appearance PBRAppearance {
              baseColor 0.305882 0.898039 0.25098
              roughness 1
              metalness 0
            }
            geometry Cylinder {
              height 0.02
              radius 0.04
              subdivision 24
            }
          }
        ]
        boundingObject USE WHEEL
        physics Physics {
        }
      }
    }
    DEF WHEEL2 HingeJoint {
      jointParameters HingeJointParameters {
        position 6.670640318240083e-17
        anchor -0.06 0 0.05
      }
      device [
        RotationalMotor {
          name "wheel2"
        }
      ]
      endPoint Solid {
        translation -0.06 0 0.05
        rotation -0.5773489356130441 -0.5773509363405651 0.5773509356129578 2.0943953064505427
        children [
          USE WHEEL
        ]
        name "solid(1)"
        boundingObject USE WHEEL
        physics Physics {
        }
      }
    }
    DEF WHEEL3 HingeJoint {
      jointParameters HingeJointParameters {
        position 1.0324509589061627e-16
        anchor 0.06 0 -0.05
      }
      device [
        RotationalMotor {
          name "wheel3"
        }
      ]
      endPoint Solid {
        translation 0.06 0 -0.05
        rotation 0.5773509358551673 0.5773499358580205 0.5773499358551123 2.0943899999969555
        children [
          USE WHEEL
        ]
        name "solid(2)"
        boundingObject USE WHEEL
        physics Physics {
        }
      }
    }
    DEF WHEEL4 HingeJoint {
      jointParameters HingeJointParameters {
        position -2.6895122773572173e-17
        anchor -0.06 0 -0.05
      }
      device [
        RotationalMotor {
          name "wheel4"
        }
      ]
      endPoint Solid {
        translation -0.06 0 -0.05
        rotation -0.5773489358690695 -0.5773509358285903 0.5773509358689082 2.0943953072187385
        children [
          USE WHEEL
        ]
        name "solid(3)"
        boundingObject USE WHEEL
        physics Physics {
        }
      }
    }
    DEF POLE HingeJoint {
      jointParameters HingeJointParameters {
        position -4.812689688184746e-16
        anchor 0 0.03000000000047226 0
        minStop -1.3
        maxStop 1.3
      }
      device [
        DEF POLE_POS_SENSOR_5 PositionSensor {
          name "polePosSensor"
        }
      ]
      endPoint Solid {
        translation -1.8379558561205137e-06 0.529996887410491 -1.1658000507824973e-10
        rotation -1.165865011598136e-10 1.1657507875994387e-10 1 1.5708000033825351
        children [
          DEF POLE_ENDPOINT_5 Solid {
            translation 0.5000000000000002 0 0
            scale 0.1 0.1 0.1
            children [
              DEF BALL Shape {
                appearance PBRAppearance {
                  baseColor 0.03137254901960784 0.047058823529411764 1
                  metalness 0
                }
                geometry Sphere {
                  radius 0.1
                }
              }
            ]
            boundingObject USE BALL
            physics Physics {
              density -1
              mass 0.02
            }
          }
          DEF POLE Shape {
            appearance PBRAppearance {
              baseColor 1 0.1568627450980392 0.1568627450980392
              roughness 1
              metalness 0
            }
            geometry Box {
              size 1 0.020000000000000004 0.019999999999999997
            }
          }
        ]
        name "pole"
        boundingObject USE POLE
        physics Physics {
          density -1
          mass 0.2
        }
      }
    }
  ]
  name "robot5"
  boundingObject USE BODY
  physics Physics {
    density -1
    mass 2
  }
  controller "robot_controller"
  supervisor TRUE
}
DEF ROBOT6 Robot {
  translation 1.2 0.04 0
  rotation 0 0 -0.9999999999999978 0
  children [
    Receiver {
      channel 6
    }
    Emitter {
      channel 6
    }
    DEF HINGE_COVER Solid {
      translation 0 0.03 -3.469446951953614e-18
      children [
        Shape {
          appearance PBRAppearance {
            baseColor 0 0.6509803921568628 1
          }
          geometry Box {
            size 0.030000000000000002 0.019999999999999997 0.05
          }
        }
      ]
      name "hingeCover"
    }
    DEF BODY Shape {
      appearance PBRAppearance {
        baseColor 0.917647 0.145098 0.145098
        roughness 1
        metalness 0
      }
      geometry Box {
        size 0.1 0.05 0.2
      }
    }
    DEF WHEEL1 HingeJoint {
      jointParameters HingeJointParameters {
        position 6.723540149111039e-17
        anchor 0.06 0 0.05
      }
      device [
        RotationalMotor {
          name "wheel1"
        }
      ]
      endPoint Solid {
        translation 0.06 0 0.05
        rotation -0.5773489359555871 -0.5773509356556262 0.5773509359553547 2.0943953074785577
        children [
          DEF WHEEL Shape {
            appearance PBRAppearance {
              baseColor 0.305882 0.898039 0.25098
              roughness 1
              metalness 0
            }
            geometry Cylinder {
              height 0.02
              radius 0.04
              subdivision 24
            }
          }
        ]
        boundingObject USE WHEEL
        physics Physics {
        }
      }
    }
    DEF WHEEL2 HingeJoint {
      jointParameters HingeJointParameters {
        position 6.670640318240083e-17
        anchor -0.06 0 0.05
      }
      device [
        RotationalMotor {
          name "wheel2"
        }
      ]
      endPoint Solid {
        translation -0.06 0 0.05
        rotation -0.5773489360060333 -0.577350935554789 0.577350936005746 2.0943953076301387
        children [
          USE WHEEL
        ]
        name "solid(1)"
        boundingObject USE WHEEL
        physics Physics {
        }
      }
    }
    DEF WHEEL3 HingeJoint {
      jointParameters HingeJointParameters {
        position 1.0324509589061627e-16
        anchor 0.06 0 -0.05
      }
      device [
        RotationalMotor {
          name "wheel3"
        }
      ]
      endPoint Solid {
        translation 0.06 0 -0.05
        rotation 0.5773509358024391 0.5773499359634153 0.5773499358024456 2.0943899998385214
        children [
          USE WHEEL
        ]
        name "solid(2)"
        boundingObject USE WHEEL
        physics Physics {
        }
      }
    }
    DEF WHEEL4 HingeJoint {
      jointParameters HingeJointParameters {
        position -2.6895122773572173e-17
        anchor -0.06 0 -0.05
      }
      device [
        RotationalMotor {
          name "wheel4"
        }
      ]
      endPoint Solid {
        translation -0.06 0 -0.05
        rotation -0.5773489359054971 -0.577350935755729 0.5773509359053419 2.0943953073281225
        children [
          USE WHEEL
        ]
        name "solid(3)"
        boundingObject USE WHEEL
        physics Physics {
        }
      }
    }
    DEF POLE HingeJoint {
      jointParameters HingeJointParameters {
        position -4.812689688184746e-16
        anchor 0 0.03000000000047226 0
        minStop -1.3
        maxStop 1.3
      }
      device [
        DEF POLE_POS_SENSOR_6 PositionSensor {
          name "polePosSensor"
        }
      ]
      endPoint Solid {
        translation -1.837955856120426e-06 0.5299968874104661 -1.166991042532164e-10
        rotation -1.1668545605511365e-10 1.1671285411992145e-10 1 1.5708000033825444
        children [
          DEF POLE_ENDPOINT_6 Solid {
            translation 0.5000000000000002 0 0
            scale 0.1 0.1 0.1
            children [
              DEF BALL Shape {
                appearance PBRAppearance {
                  baseColor 0.03137254901960784 0.047058823529411764 1
                  metalness 0
                }
                geometry Sphere {
                  radius 0.1
                }
              }
            ]
            boundingObject USE BALL
            physics Physics {
              density -1
              mass 0.02
            }
          }
          DEF POLE Shape {
            appearance PBRAppearance {
              baseColor 1 0.1568627450980392 0.1568627450980392
              roughness 1
              metalness 0
            }
            geometry Box {
              size 1 0.020000000000000004 0.019999999999999997
            }
          }
        ]
        name "pole"
        boundingObject USE POLE
        physics Physics {
          density -1
          mass 0.2
        }
      }
    }
  ]
  name "robot6"
  boundingObject USE BODY
  physics Physics {
    density -1
    mass 2
  }
  controller "robot_controller"
  supervisor TRUE
}
DEF ROBOT7 Robot {
  translation 0 0.04 1.2
  rotation 0 0 -0.9999999999999978 0
  children [
    Receiver {
      channel 7
    }
    Emitter {
      channel 7
    }
    DEF HINGE_COVER Solid {
      translation 0 0.03 -3.469446951953614e-18
      children [
        Shape {
          appearance PBRAppearance {
            baseColor 0 0.6509803921568628 1
          }
          geometry Box {
            size 0.030000000000000002 0.019999999999999997 0.05
          }
        }
      ]
      name "hingeCover"
    }
    DEF BODY Shape {
      appearance PBRAppearance {
        baseColor 0.917647 0.145098 0.145098
        roughness 1
        metalness 0
      }
      geometry Box {
        size 0.1 0.05 0.2
      }
    }
    DEF WHEEL1 HingeJoint {
      jointParameters HingeJointParameters {
        position 6.723540149111039e-17
        anchor 0.06 0 0.05
      }
      device [
        RotationalMotor {
          name "wheel1"
        }
      ]
      endPoint Solid {
        translation 0.06 0 0.05
        rotation -0.5773489357835588 -0.5773509359996348 0.5773509357833739 2.0943953069622188
        children [
          DEF WHEEL Shape {
            appearance PBRAppearance {
              baseColor 0.305882 0.898039 0.25098
              roughness 1
              metalness 0
            }
            geometry Cylinder {
              height 0.02
              radius 0.04
              subdivision 24
            }
          }
        ]
        boundingObject USE WHEEL
        physics Physics {
        }
      }
    }
    DEF WHEEL2 HingeJoint {
      jointParameters HingeJointParameters {
        position 6.670640318240083e-17
        anchor -0.06 0 0.05
      }
      device [
        RotationalMotor {
          name "wheel2"
        }
      ]
      endPoint Solid {
        translation -0.06 0 0.05
        rotation -0.5773489358102495 -0.5773509359462426 0.5773509358100757 2.0943953070422903
        children [
          USE WHEEL
        ]
        name "solid(1)"
        boundingObject USE WHEEL
        physics Physics {
        }
      }
    }
    DEF WHEEL3 HingeJoint {
      jointParameters HingeJointParameters {
        position 1.0324509589061627e-16
        anchor 0.06 0 -0.05
      }
      device [
        RotationalMotor {
          name "wheel3"
        }
      ]
      endPoint Solid {
        translation 0.06 0 -0.05
        rotation 0.5773509359951603 0.577349935577991 0.5773499359951485 2.094390000416376
        children [
          USE WHEEL
        ]
        name "solid(2)"
        boundingObject USE WHEEL
        physics Physics {
        }
      }
    }
    DEF WHEEL4 HingeJoint {
      jointParameters HingeJointParameters {
        position -2.6895122773572173e-17
        anchor -0.06 0 -0.05
      }
      device [
        RotationalMotor {
          name "wheel4"
        }
      ]
      endPoint Solid {
        translation -0.06 0 -0.05
        rotation -0.5773489358206021 -0.5773509359255689 0.5773509358203968 2.0943953070732526
        children [
          USE WHEEL
        ]
        name "solid(3)"
        boundingObject USE WHEEL
        physics Physics {
        }
      }
    }
    DEF POLE HingeJoint {
      jointParameters HingeJointParameters {
        position -4.812689688184746e-16
        anchor 0 0.03000000000047226 0
        minStop -1.3
        maxStop 1.3
      }
      device [
        DEF POLE_POS_SENSOR_7 PositionSensor {
          name "polePosSensor"
        }
      ]
      endPoint Solid {
        translation -1.8379558561204908e-06 0.5299968874104941 -1.165904411746812e-10
        rotation -1.165905441404668e-10 1.1658928807057834e-10 1 1.5708000033824618
        children [
          DEF POLE_ENDPOINT_7 Solid {
            translation 0.5000000000000002 0 0
            scale 0.1 0.1 0.1
            children [
              DEF BALL Shape {
                appearance PBRAppearance {
                  baseColor 0.03137254901960784 0.047058823529411764 1
                  metalness 0
                }
                geometry Sphere {
                  radius 0.1
                }
              }
            ]
            boundingObject USE BALL
            physics Physics {
              density -1
              mass 0.02
            }
          }
          DEF POLE Shape {
            appearance PBRAppearance {
              baseColor 1 0.1568627450980392 0.1568627450980392
              roughness 1
              metalness 0
            }
            geometry Box {
              size 1 0.020000000000000004 0.019999999999999997
            }
          }
        ]
        name "pole"
        boundingObject USE POLE
        physics Physics {
          density -1
          mass 0.2
        }
      }
    }
  ]
  name "robot7"
  boundingObject USE BODY
  physics Physics {
    density -1
    mass 2
  }
  controller "robot_controller"
  supervisor TRUE
}
DEF ROBOT8 Robot {
  translation 1.2 0.04 1.2
  rotation 0 0 -0.9999999999999978 0
  children [
    Receiver {
      channel 8
    }
    Emitter {
      channel 8
    }
    DEF HINGE_COVER Solid {
      translation 0 0.03 -3.469446951953614e-18
      children [
        Shape {
          appearance PBRAppearance {
            baseColor 0 0.6509803921568628 1
          }
          geometry Box {
            size 0.030000000000000002 0.019999999999999997 0.05
          }
        }
      ]
      name "hingeCover"
    }
    DEF BODY Shape {
      appearance PBRAppearance {
        baseColor 0.917647 0.145098 0.145098
        roughness 1
        metalness 0
      }
      geometry Box {
        size 0.1 0.05 0.2
      }
    }
    DEF WHEEL1 HingeJoint {
      jointParameters HingeJointParameters {
        position 6.723540149111039e-17
        anchor 0.06 0 0.05
      }
      device [
        RotationalMotor {
          name "wheel1"
        }
      ]
      endPoint Solid {
        translation 0.06 0 0.05
        rotation -0.5773489359431471 -0.5773509356804635 0.5773509359429576 2.0943953074409447
        children [
          DEF WHEEL Shape {
            appearance PBRAppearance {
              baseColor 0.305882 0.898039 0.25098
              roughness 1
              metalness 0
            }
            geometry Cylinder {
              height 0.02
              radius 0.04
              subdivision 24
            }
          }
        ]
        boundingObject USE WHEEL
        physics Physics {
        }
      }
    }
    DEF WHEEL2 HingeJoint {
      jointParameters HingeJointParameters {
        position 6.670640318240083e-17
        anchor -0.06 0 0.05
      }
      device [
        RotationalMotor {
          name "wheel2"
        }
      ]
      endPoint Solid {
        translation -0.06 0 0.05
        rotation -0.5773489358857566 -0.5773509357953298 0.5773509358854815 2.0943953072692683
        children [
          USE WHEEL
        ]
        name "solid(1)"
        boundingObject USE WHEEL
        physics Physics {
        }
      }
    }
    DEF WHEEL3 HingeJoint {
      jointParameters HingeJointParameters {
        position 1.0324509589061627e-16
        anchor 0.06 0 -0.05
      }
      device [
        RotationalMotor {
          name "wheel3"
        }
      ]
      endPoint Solid {
        translation 0.06 0 -0.05
        rotation 0.5773509358677961 0.5773499358327902 0.5773499358677138 2.094390000034776
        children [
          USE WHEEL
        ]
        name "solid(2)"
        boundingObject USE WHEEL
        physics Physics {
        }
      }
    }
    DEF WHEEL4 HingeJoint {
      jointParameters HingeJointParameters {
        position -2.6895122773572173e-17
        anchor -0.06 0 -0.05
      }
      device [
        RotationalMotor {
          name "wheel4"
        }
      ]
      endPoint Solid {
        translation -0.06 0 -0.05
        rotation -0.5773489358351139 -0.5773509358965402 0.5773509358349135 2.0943953071167734
        children [
          USE WHEEL
        ]
        name "solid(3)"
        boundingObject USE WHEEL
        physics Physics {
        }
      }
    }
    DEF POLE HingeJoint {
      jointParameters HingeJointParameters {
        position -4.812689688184746e-16
        anchor 0 0.03000000000047226 0
        minStop -1.3
        maxStop 1.3
      }
      device [
        DEF POLE_POS_SENSOR_8 PositionSensor {
          name "polePosSensor"
        }
      ]
      endPoint Solid {
        translation -1.8379558561205268e-06 0.5299968874104899 -1.1662427522135666e-10
        rotation -1.1660958147652356e-10 1.1663242628157146e-10 1 1.5708000033826095
        children [
          DEF POLE_ENDPOINT_8 Solid {
            translation 0.5000000000000002 0 0
            scale 0.1 0.1 0.1
            children [
              DEF BALL Shape {
                appearance PBRAppearance {
                  baseColor 0.03137254901960784 0.047058823529411764 1
                  metalness 0
                }
                geometry Sphere {
                  radius 0.1
                }
              }
            ]
            boundingObject USE BALL
            physics Physics {
              density -1
              mass 0.02
            }
          }
          DEF POLE Shape {
            appearance PBRAppearance {
              baseColor 1 0.1568627450980392 0.1568627450980392
              roughness 1
              metalness 0
            }
            geometry Box {
              size 1 0.020000000000000004 0.019999999999999997
            }
          }
        ]
        name "pole"
        boundingObject USE POLE
        physics Physics {
          density -1
          mass 0.2
        }
      }
    }
  ]
  name "robot8"
  boundingObject USE BODY
  physics Physics {
    density -1
    mass 2
  }
  controller "robot_controller"
  supervisor TRUE
}
DEF ROBOT0 Robot {
  translation -1.2 0.04 -1.2
  rotation 0 0 -0.9999999999999978 0
  children [
    Receiver {
    }
    Emitter {
    }
    DEF HINGE_COVER Solid {
      translation 0 0.03 -3.469446951953614e-18
      children [
        Shape {
          appearance PBRAppearance {
            baseColor 0 0.6509803921568628 1
          }
          geometry Box {
            size 0.030000000000000002 0.019999999999999997 0.05
          }
        }
      ]
      name "hingeCover"
    }
    DEF BODY Shape {
      appearance PBRAppearance {
        baseColor 0.917647 0.145098 0.145098
        roughness 1
        metalness 0
      }
      geometry Box {
        size 0.1 0.05 0.2
      }
    }
    DEF WHEEL1 HingeJoint {
      jointParameters HingeJointParameters {
        position 6.723540149111039e-17
        anchor 0.06 0 0.05
      }
      device [
        RotationalMotor {
          name "wheel1"
        }
      ]
      endPoint Solid {
        translation 0.06 0 0.05
        rotation -0.5773489358320916 -0.5773509359025693 0.5773509358319068 2.094395307107651
        children [
          DEF WHEEL Shape {
            appearance PBRAppearance {
              baseColor 0.305882 0.898039 0.25098
              roughness 1
              metalness 0
            }
            geometry Cylinder {
              height 0.02
              radius 0.04
              subdivision 24
            }
          }
        ]
        boundingObject USE WHEEL
        physics Physics {
        }
      }
    }
    DEF WHEEL2 HingeJoint {
      jointParameters HingeJointParameters {
        position 6.670640318240083e-17
        anchor -0.06 0 0.05
      }
      device [
        RotationalMotor {
          name "wheel2"
        }
      ]
      endPoint Solid {
        translation -0.06 0 0.05
        rotation -0.5773489358150751 -0.5773509359366137 0.5773509358148787 2.094395307056659
        children [
          USE WHEEL
        ]
        name "solid(1)"
        boundingObject USE WHEEL
        physics Physics {
        }
      }
    }
    DEF WHEEL3 HingeJoint {
      jointParameters HingeJointParameters {
        position 1.0324509589061627e-16
        anchor 0.06 0 -0.05
      }
      device [
        RotationalMotor {
          name "wheel3"
        }
      ]
      endPoint Solid {
        translation 0.06 0 -0.05
        rotation 0.5773509358465633 0.577349935875195 0.5773499358465419 2.094389999971118
        children [
          USE WHEEL
        ]
        name "solid(2)"
        boundingObject USE WHEEL
        physics Physics {
        }
      }
    }
    DEF WHEEL4 HingeJoint {
      jointParameters HingeJointParameters {
        position -2.6895122773572173e-17
        anchor -0.06 0 -0.05
      }
      device [
        RotationalMotor {
          name "wheel4"
        }
      ]
      endPoint Solid {
        translation -0.06 0 -0.05
        rotation -0.5773489358263025 -0.5773509359142032 0.5773509358260619 2.094395307090379
        children [
          USE WHEEL
        ]
        name "solid(3)"
        boundingObject USE WHEEL
        physics Physics {
        }
      }
    }
    DEF POLE HingeJoint {
      jointParameters HingeJointParameters {
        position -4.812689688184746e-16
        anchor 0 0.03000000000047226 0
        minStop -1.3
        maxStop 1.3
      }
      device [
        DEF POLE_POS_SENSOR_0 PositionSensor {
          name "polePosSensor"
        }
      ]
      endPoint Solid {
        translation -1.8379558561204925e-06 0.5299968874104712 2.1624948959454977e-09
        rotation 2.1625086942152185e-09 -2.1625072026283554e-09 1 1.5708000033825311
        children [
          DEF POLE_ENDPOINT_0 Solid {
            translation 0.5000000000000002 0 0
            scale 0.1 0.1 0.1
            children [
              DEF BALL Shape {
                appearance PBRAppearance {
                  baseColor 0.03137254901960784 0.047058823529411764 1
                  metalness 0
                }
                geometry Sphere {
                  radius 0.1
                }
              }
            ]
            boundingObject USE BALL
            physics Physics {
              density -1
              mass 0.02
            }
          }
          DEF POLE Shape {
            appearance PBRAppearance {
              baseColor 1 0.1568627450980392 0.1568627450980392
              roughness 1
              metalness 0
            }
            geometry Box {
              size 1 0.020000000000000004 0.019999999999999997
            }
          }
        ]
        name "pole"
        boundingObject USE POLE
        physics Physics {
          density -1
          mass 0.2
        }
      }
    }
  ]
  name "robot0"
  boundingObject USE BODY
  physics Physics {
    density -1
    mass 2
  }
  controller "robot_controller"
  supervisor TRUE
}
