#VRML_SIM R2021a utf8
WorldInfo {
  coordinateSystem "NUE"
}
Viewpoint {
  orientation -0.13958363967751458 -0.9678947727217598 -0.2090361606810427 2.0229067928845246
  position -11.277758714100244 6.293648486056089 -4.752450043214204
}
TexturedBackground {
}
TexturedBackgroundLight {
}
RectangleArena {
  rotation 0 1 0 4.6928e-06
  floorSize 3.4 3.4
  floorTileSize 0.4 0.4
  floorAppearance Parquetry {
  }
  wallThickness 0.2
  wallHeight 0.2
}
DEF SUPERVISOR Robot {
  children [
    Emitter {
    }
    Receiver {
      name "receiver3"
    }
    Emitter {
      name "emitter3"
    }
    Receiver {
      name "receiver2"
    }
    Emitter {
      name "emitter2"
    }
    Receiver {
      name "receiver1"
    }
    Emitter {
      name "emitter1"
    }
    Receiver {
      name "receiver0"
    }
    Emitter {
      name "emitter0"
    }
  ]
  name "supervisor"
  controller "supervisor_manager"
  supervisor TRUE
}
DEF ROBOT4 Robot {
  translation 0 0.045 0.01
  rotation 0 0 -0.9999999999999978 0
  children [
    DEF EMITTER Emitter {
    }
    DEF RECEIVER Receiver {
    }
    DEF HINGE_COVER Solid {
      translation 0 0.03 -3.469446951953614e-18
      children [
        Shape {
          appearance PBRAppearance {
            baseColor 0 0.6509803921568628 1
          }
          geometry Box {
            size 0.030000000000000002 0.019999999999999997 0.05
          }
        }
      ]
      name "hingeCover"
    }
    DEF BODY Shape {
      appearance PBRAppearance {
        baseColor 0.917647 0.145098 0.145098
        roughness 1
        metalness 0
      }
      geometry Box {
        size 0.1 0.05 0.2
      }
    }
    DEF WHEEL1 HingeJoint {
      jointParameters HingeJointParameters {
        position 6.723540149111039e-17
        anchor 0.06 0 0.05
      }
      device [
        RotationalMotor {
          name "wheel1"
        }
      ]
      endPoint Solid {
        translation 0.06 0 0.05
        rotation 2.847458713879346e-14 -2.871010106898979e-14 1 1.5708000000006916
        children [
          DEF WHEEL Shape {
            appearance PBRAppearance {
              baseColor 0.305882 0.898039 0.25098
              roughness 1
              metalness 0
            }
            geometry Cylinder {
              height 0.02
              radius 0.04
              subdivision 24
            }
          }
        ]
        boundingObject USE WHEEL
        physics Physics {
        }
      }
    }
    DEF WHEEL2 HingeJoint {
      jointParameters HingeJointParameters {
        position 6.670640318240083e-17
        anchor -0.06 0 0.05
      }
      device [
        RotationalMotor {
          name "wheel2"
        }
      ]
      endPoint Solid {
        translation -0.06 0 0.05
        rotation 2.8630538103567804e-14 -2.7766989327339155e-14 1 1.5708000000006919
        children [
          USE WHEEL
        ]
        name "solid(1)"
        boundingObject USE WHEEL
        physics Physics {
        }
      }
    }
    DEF WHEEL3 HingeJoint {
      jointParameters HingeJointParameters {
        position 1.0324509589061627e-16
        anchor 0.06 0 -0.05
      }
      device [
        RotationalMotor {
          name "wheel3"
        }
      ]
      endPoint Solid {
        translation 0.06 0 -0.05
        rotation 4.3069934832313004e-14 -4.416899829333131e-14 1 1.570800000000692
        children [
          USE WHEEL
        ]
        name "solid(2)"
        boundingObject USE WHEEL
        physics Physics {
        }
      }
    }
    DEF WHEEL4 HingeJoint {
      jointParameters HingeJointParameters {
        position -2.6895122773572173e-17
        anchor -0.06 0 -0.05
      }
      device [
        RotationalMotor {
          name "wheel4"
        }
      ]
      endPoint Solid {
        translation -0.06 0 -0.05
        rotation -1.1201426030857949e-14 1.1044417270934688e-14 1 1.5708000000006879
        children [
          USE WHEEL
        ]
        name "solid(3)"
        boundingObject USE WHEEL
        physics Physics {
        }
      }
    }
    DEF POLE HingeJoint {
      jointParameters HingeJointParameters {
        position -4.812689688184746e-16
        anchor 0 0.03000000000047226 0
        minStop -1.3
        maxStop 1.3
      }
      device [
        DEF POLE_POS_SENSOR PositionSensor {
          name "polePosSensor"
        }
      ]
      endPoint Solid {
        translation -1.8379558561220375e-06 0.5299968874104757 -2.0449416793507185e-13
        rotation -2.0428913402448601e-13 2.0413212860609618e-13 1 1.5708000033841265
        children [
          DEF POLE_ENDPOINT_4 Solid {
            translation 0.5000000000000002 0 0
            scale 0.1 0.1 0.1
            children [
              DEF BALL Shape {
                appearance PBRAppearance {
                  baseColor 0.03137254901960784 0.047058823529411764 1
                  metalness 0
                }
                geometry Sphere {
                  radius 0.1
                }
              }
            ]
            boundingObject USE BALL
            physics Physics {
              density -1
              mass 0.02
            }
          }
          DEF POLE Shape {
            appearance PBRAppearance {
              baseColor 1 0.1568627450980392 0.1568627450980392
              roughness 1
              metalness 0
            }
            geometry Box {
              size 1 0.020000000000000004 0.019999999999999997
            }
          }
        ]
        name "pole"
        boundingObject USE POLE
        physics Physics {
          density -1
          mass 0.2
        }
      }
    }
  ]
  name "robot4"
  boundingObject USE BODY
  physics Physics {
    density -1
    mass 2
  }
  controller "robot_controller"
}
DEF ROBOT5 Robot {
  translation -1.19 0.045 -0.01
  rotation 0 0 -0.9999999999999978 0
  children [
    DEF EMITTER Emitter {
    }
    DEF RECEIVER Receiver {
    }
    DEF HINGE_COVER Solid {
      translation 0 0.03 -3.469446951953614e-18
      children [
        Shape {
          appearance PBRAppearance {
            baseColor 0 0.6509803921568628 1
          }
          geometry Box {
            size 0.030000000000000002 0.019999999999999997 0.05
          }
        }
      ]
      name "hingeCover"
    }
    DEF BODY Shape {
      appearance PBRAppearance {
        baseColor 0.917647 0.145098 0.145098
        roughness 1
        metalness 0
      }
      geometry Box {
        size 0.1 0.05 0.2
      }
    }
    DEF WHEEL1 HingeJoint {
      jointParameters HingeJointParameters {
        position 6.723540149111039e-17
        anchor 0.06 0 0.05
      }
      device [
        RotationalMotor {
          name "wheel1"
        }
      ]
      endPoint Solid {
        translation 0.06 0 0.05
        rotation 2.941664088382673e-14 -2.8239074196473228e-14 1 1.570800000000688
        children [
          DEF WHEEL Shape {
            appearance PBRAppearance {
              baseColor 0.305882 0.898039 0.25098
              roughness 1
              metalness 0
            }
            geometry Cylinder {
              height 0.02
              radius 0.04
              subdivision 24
            }
          }
        ]
        boundingObject USE WHEEL
        physics Physics {
        }
      }
    }
    DEF WHEEL2 HingeJoint {
      jointParameters HingeJointParameters {
        position 6.670640318240083e-17
        anchor -0.06 0 0.05
      }
      device [
        RotationalMotor {
          name "wheel2"
        }
      ]
      endPoint Solid {
        translation -0.06 0 0.05
        rotation 2.847352914606234e-14 -2.7688484848586446e-14 1 1.5708000000006865
        children [
          USE WHEEL
        ]
        name "solid(1)"
        boundingObject USE WHEEL
        physics Physics {
        }
      }
    }
    DEF WHEEL3 HingeJoint {
      jointParameters HingeJointParameters {
        position 1.0324509589061627e-16
        anchor 0.06 0 -0.05
      }
      device [
        RotationalMotor {
          name "wheel3"
        }
      ]
      endPoint Solid {
        translation 0.06 0 -0.05
        rotation 4.47970333648739e-14 -4.369797142081469e-14 1 1.5708000000006925
        children [
          USE WHEEL
        ]
        name "solid(2)"
        boundingObject USE WHEEL
        physics Physics {
        }
      }
    }
    DEF WHEEL4 HingeJoint {
      jointParameters HingeJointParameters {
        position -2.6895122773572173e-17
        anchor -0.06 0 -0.05
      }
      device [
        RotationalMotor {
          name "wheel4"
        }
      ]
      endPoint Solid {
        translation -0.06 0 -0.05
        rotation -1.1358434988363474e-14 1.0808903834676374e-14 1 1.5708000000006899
        children [
          USE WHEEL
        ]
        name "solid(3)"
        boundingObject USE WHEEL
        physics Physics {
        }
      }
    }
    DEF POLE HingeJoint {
      jointParameters HingeJointParameters {
        position -4.812689688184746e-16
        anchor 0 0.03000000000047226 0
        minStop -1.3
        maxStop 1.3
      }
      device [
        DEF POLE_POS_SENSOR PositionSensor {
          name "polePosSensor"
        }
      ]
      endPoint Solid {
        translation -1.8379558561220515e-06 0.5299968874104807 -2.0446641235945622e-13
        rotation -2.0436763850310585e-13 2.052311913067755e-13 1 1.570800003384128
        children [
          DEF POLE_ENDPOINT_5 Solid {
            translation 0.5000000000000002 0 0
            scale 0.1 0.1 0.1
            children [
              DEF BALL Shape {
                appearance PBRAppearance {
                  baseColor 0.03137254901960784 0.047058823529411764 1
                  metalness 0
                }
                geometry Sphere {
                  radius 0.1
                }
              }
            ]
            boundingObject USE BALL
            physics Physics {
              density -1
              mass 0.02
            }
          }
          DEF POLE Shape {
            appearance PBRAppearance {
              baseColor 1 0.1568627450980392 0.1568627450980392
              roughness 1
              metalness 0
            }
            geometry Box {
              size 1 0.020000000000000004 0.019999999999999997
            }
          }
        ]
        name "pole"
        boundingObject USE POLE
        physics Physics {
          density -1
          mass 0.2
        }
      }
    }
  ]
  name "robot5"
  boundingObject USE BODY
  physics Physics {
    density -1
    mass 2
  }
  controller "robot_controller"
}
DEF ROBOT8 Robot {
  translation -1.19 0.045 -1.2
  rotation 0 0 -0.9999999999999978 0
  children [
    DEF EMITTER Emitter {
    }
    DEF RECEIVER Receiver {
    }
    DEF HINGE_COVER Solid {
      translation 0 0.03 -3.469446951953614e-18
      children [
        Shape {
          appearance PBRAppearance {
            baseColor 0 0.6509803921568628 1
          }
          geometry Box {
            size 0.030000000000000002 0.019999999999999997 0.05
          }
        }
      ]
      name "hingeCover"
    }
    DEF BODY Shape {
      appearance PBRAppearance {
        baseColor 0.917647 0.145098 0.145098
        roughness 1
        metalness 0
      }
      geometry Box {
        size 0.1 0.05 0.2
      }
    }
    DEF WHEEL1 HingeJoint {
      jointParameters HingeJointParameters {
        position 6.723540149111039e-17
        anchor 0.06 0 0.05
      }
      device [
        RotationalMotor {
          name "wheel1"
        }
      ]
      endPoint Solid {
        translation 0.06 0 0.05
        rotation 3.028019015010718e-14 -2.8239074196473243e-14 1 1.5708000000006879
        children [
          DEF WHEEL Shape {
            appearance PBRAppearance {
              baseColor 0.305882 0.898039 0.25098
              roughness 1
              metalness 0
            }
            geometry Cylinder {
              height 0.02
              radius 0.04
              subdivision 24
            }
          }
        ]
        boundingObject USE WHEEL
        physics Physics {
        }
      }
    }
    DEF WHEEL2 HingeJoint {
      jointParameters HingeJointParameters {
        position 6.670640318240083e-17
        anchor -0.06 0 0.05
      }
      device [
        RotationalMotor {
          name "wheel2"
        }
      ]
      endPoint Solid {
        translation -0.06 0 0.05
        rotation 2.894455601857892e-14 -2.8238016199855804e-14 1 1.570800000000689
        children [
          USE WHEEL
        ]
        name "solid(1)"
        boundingObject USE WHEEL
        physics Physics {
        }
      }
    }
    DEF WHEEL3 HingeJoint {
      jointParameters HingeJointParameters {
        position 1.0324509589061627e-16
        anchor 0.06 0 -0.05
      }
      device [
        RotationalMotor {
          name "wheel3"
        }
      ]
      endPoint Solid {
        translation 0.06 0 -0.05
        rotation 4.440451097111018e-14 -4.385498037832033e-14 1 1.5708000000006874
        children [
          USE WHEEL
        ]
        name "solid(2)"
        boundingObject USE WHEEL
        physics Physics {
        }
      }
    }
    DEF WHEEL4 HingeJoint {
      jointParameters HingeJointParameters {
        position -2.6895122773572173e-17
        anchor -0.06 0 -0.05
      }
      device [
        RotationalMotor {
          name "wheel4"
        }
      ]
      endPoint Solid {
        translation -0.06 0 -0.05
        rotation -1.4420109659721443e-14 1.1672453100956832e-14 1 1.570800000000688
        children [
          USE WHEEL
        ]
        name "solid(3)"
        boundingObject USE WHEEL
        physics Physics {
        }
      }
    }
    DEF POLE HingeJoint {
      jointParameters HingeJointParameters {
        position -4.812689688184746e-16
        anchor 0 0.03000000000047226 0
        minStop -1.3
        maxStop 1.3
      }
      device [
        DEF POLE_POS_SENSOR PositionSensor {
          name "polePosSensor"
        }
      ]
      endPoint Solid {
        translation -1.8379558561220549e-06 0.529996887410481 -2.0432763448137808e-13
        rotation -2.044461429817259e-13 2.0515268682815562e-13 1 1.5708000033841274
        children [
          DEF POLE_ENDPOINT_8 Solid {
            translation 0.5000000000000002 0 0
            scale 0.1 0.1 0.1
            children [
              DEF BALL Shape {
                appearance PBRAppearance {
                  baseColor 0.03137254901960784 0.047058823529411764 1
                  metalness 0
                }
                geometry Sphere {
                  radius 0.1
                }
              }
            ]
            boundingObject USE BALL
            physics Physics {
              density -1
              mass 0.02
            }
          }
          DEF POLE Shape {
            appearance PBRAppearance {
              baseColor 1 0.1568627450980392 0.1568627450980392
              roughness 1
              metalness 0
            }
            geometry Box {
              size 1 0.020000000000000004 0.019999999999999997
            }
          }
        ]
        name "pole"
        boundingObject USE POLE
        physics Physics {
          density -1
          mass 0.2
        }
      }
    }
  ]
  name "robot8"
  boundingObject USE BODY
  physics Physics {
    density -1
    mass 2
  }
  controller "robot_controller"
}
DEF ROBOT7 Robot {
  translation 0 0.045 -1.2
  rotation 0 0 -0.9999999999999978 0
  children [
    DEF EMITTER Emitter {
    }
    DEF RECEIVER Receiver {
    }
    DEF HINGE_COVER Solid {
      translation 0 0.03 -3.469446951953614e-18
      children [
        Shape {
          appearance PBRAppearance {
            baseColor 0 0.6509803921568628 1
          }
          geometry Box {
            size 0.030000000000000002 0.019999999999999997 0.05
          }
        }
      ]
      name "hingeCover"
    }
    DEF BODY Shape {
      appearance PBRAppearance {
        baseColor 0.917647 0.145098 0.145098
        roughness 1
        metalness 0
      }
      geometry Box {
        size 0.1 0.05 0.2
      }
    }
    DEF WHEEL1 HingeJoint {
      jointParameters HingeJointParameters {
        position 6.723540149111039e-17
        anchor 0.06 0 0.05
      }
      device [
        RotationalMotor {
          name "wheel1"
        }
      ]
      endPoint Solid {
        translation 0.06 0 0.05
        rotation 2.9652154320085016e-14 -2.9141875702130047e-14 1 1.5708000000006896
        children [
          DEF WHEEL Shape {
            appearance PBRAppearance {
              baseColor 0.305882 0.898039 0.25098
              roughness 1
              metalness 0
            }
            geometry Cylinder {
              height 0.02
              radius 0.04
              subdivision 24
            }
          }
        ]
        boundingObject USE WHEEL
        physics Physics {
        }
      }
    }
    DEF WHEEL2 HingeJoint {
      jointParameters HingeJointParameters {
        position 6.670640318240083e-17
        anchor -0.06 0 0.05
      }
      device [
        RotationalMotor {
          name "wheel2"
        }
      ]
      endPoint Solid {
        translation -0.06 0 0.05
        rotation 2.9847357524235744e-14 -2.8591286354243243e-14 1 1.5708000000006896
        children [
          USE WHEEL
        ]
        name "solid(1)"
        boundingObject USE WHEEL
        physics Physics {
        }
      }
    }
    DEF WHEEL3 HingeJoint {
      jointParameters HingeJointParameters {
        position 1.0324509589061627e-16
        anchor 0.06 0 -0.05
      }
      device [
        RotationalMotor {
          name "wheel3"
        }
      ]
      endPoint Solid {
        translation 0.06 0 -0.05
        rotation 4.255965572042007e-14 -4.361946694206199e-14 1 1.5708000000006896
        children [
          USE WHEEL
        ]
        name "solid(2)"
        boundingObject USE WHEEL
        physics Physics {
        }
      }
    }
    DEF WHEEL4 HingeJoint {
      jointParameters HingeJointParameters {
        position -2.6895122773572173e-17
        anchor -0.06 0 -0.05
      }
      device [
        RotationalMotor {
          name "wheel4"
        }
      ]
      endPoint Solid {
        translation -0.06 0 -0.05
        rotation -9.31731854079149e-15 1.1240678467816585e-14 1 1.5708000000006919
        children [
          USE WHEEL
        ]
        name "solid(3)"
        boundingObject USE WHEEL
        physics Physics {
        }
      }
    }
    DEF POLE HingeJoint {
      jointParameters HingeJointParameters {
        position -4.812689688184746e-16
        anchor 0 0.03000000000047226 0
        minStop -1.3
        maxStop 1.3
      }
      device [
        DEF POLE_POS_SENSOR PositionSensor {
          name "polePosSensor"
        }
      ]
      endPoint Solid {
        translation -1.8379558561220418e-06 0.5299968874104786 -2.047439681156125e-13
        rotation -2.0538819672516542e-13 2.0452465099919592e-13 1 1.5708000033841274
        children [
          DEF POLE_ENDPOINT_7 Solid {
            translation 0.5000000000000002 0 0
            scale 0.1 0.1 0.1
            children [
              DEF BALL Shape {
                appearance PBRAppearance {
                  baseColor 0.03137254901960784 0.047058823529411764 1
                  metalness 0
                }
                geometry Sphere {
                  radius 0.1
                }
              }
            ]
            boundingObject USE BALL
            physics Physics {
              density -1
              mass 0.02
            }
          }
          DEF POLE Shape {
            appearance PBRAppearance {
              baseColor 1 0.1568627450980392 0.1568627450980392
              roughness 1
              metalness 0
            }
            geometry Box {
              size 1 0.020000000000000004 0.019999999999999997
            }
          }
        ]
        name "pole"
        boundingObject USE POLE
        physics Physics {
          density -1
          mass 0.2
        }
      }
    }
  ]
  name "robot7"
  boundingObject USE BODY
  physics Physics {
    density -1
    mass 2
  }
  controller "robot_controller"
}
DEF ROBOT6 Robot {
  translation 1.2 0.045 -1.21
  children [
    DEF EMITTER Emitter {
    }
    DEF RECEIVER Receiver {
    }
    DEF HINGE_COVER Solid {
      translation 0 0.03 -3.469446951953614e-18
      children [
        Shape {
          appearance PBRAppearance {
            baseColor 0 0.6509803921568628 1
          }
          geometry Box {
            size 0.030000000000000002 0.019999999999999997 0.05
          }
        }
      ]
      name "hingeCover"
    }
    DEF BODY Shape {
      appearance PBRAppearance {
        baseColor 0.917647 0.145098 0.145098
        roughness 1
        metalness 0
      }
      geometry Box {
        size 0.1 0.05 0.2
      }
    }
    DEF WHEEL1 HingeJoint {
      jointParameters HingeJointParameters {
        position 6.723540149111039e-17
        anchor 0.06 0 0.05
      }
      device [
        RotationalMotor {
          name "wheel1"
        }
      ]
      endPoint Solid {
        translation 0.06 0 0.05
        rotation 2.9652154320085003e-14 -2.9338136899011963e-14 1 1.5708000000006899
        children [
          DEF WHEEL Shape {
            appearance PBRAppearance {
              baseColor 0.305882 0.898039 0.25098
              roughness 1
              metalness 0
            }
            geometry Cylinder {
              height 0.02
              radius 0.04
              subdivision 24
            }
          }
        ]
        boundingObject USE WHEEL
        physics Physics {
        }
      }
    }
    DEF WHEEL2 HingeJoint {
      jointParameters HingeJointParameters {
        position 6.670640318240083e-17
        anchor -0.06 0 0.05
      }
      device [
        RotationalMotor {
          name "wheel2"
        }
      ]
      endPoint Solid {
        translation -0.06 0 0.05
        rotation 2.745297092227632e-14 -2.8473529636114115e-14 1 1.5708000000006883
        children [
          USE WHEEL
        ]
        name "solid(1)"
        boundingObject USE WHEEL
        physics Physics {
        }
      }
    }
    DEF WHEEL3 HingeJoint {
      jointParameters HingeJointParameters {
        position 1.0324509589061627e-16
        anchor 0.06 0 -0.05
      }
      device [
        RotationalMotor {
          name "wheel3"
        }
      ]
      endPoint Solid {
        translation 0.06 0 -0.05
        rotation 4.3226943789818605e-14 -4.354096246330921e-14 1 1.5708000000006896
        children [
          USE WHEEL
        ]
        name "solid(2)"
        boundingObject USE WHEEL
        physics Physics {
        }
      }
    }
    DEF WHEEL4 HingeJoint {
      jointParameters HingeJointParameters {
        position -2.6895122773572173e-17
        anchor -0.06 0 -0.05
      }
      device [
        RotationalMotor {
          name "wheel4"
        }
      ]
      endPoint Solid {
        translation -0.06 0 -0.05
        rotation -1.0573390200835804e-14 1.0494885919665309e-14 1 1.570800000000688
        children [
          USE WHEEL
        ]
        name "solid(3)"
        boundingObject USE WHEEL
        physics Physics {
        }
      }
    }
    DEF POLE HingeJoint {
      jointParameters HingeJointParameters {
        position -4.812689688184746e-16
        anchor 0 0.03000000000047226 0
        minStop -1.3
        maxStop 1.3
      }
      device [
        DEF POLE_POS_SENSOR PositionSensor {
          name "polePosSensor"
        }
      ]
      endPoint Solid {
        translation -1.837955856122043e-06 0.5299968874104781 -2.0457743466191874e-13
        rotation -2.0585922359688491e-13 2.0530969578539527e-13 1 1.57080000338413
        children [
          DEF POLE_ENDPOINT_6 Solid {
            translation 0.5000000000000002 0 0
            scale 0.1 0.1 0.1
            children [
              DEF BALL Shape {
                appearance PBRAppearance {
                  baseColor 0.03137254901960784 0.047058823529411764 1
                  metalness 0
                }
                geometry Sphere {
                  radius 0.1
                }
              }
            ]
            boundingObject USE BALL
            physics Physics {
              density -1
              mass 0.02
            }
          }
          DEF POLE Shape {
            appearance PBRAppearance {
              baseColor 1 0.1568627450980392 0.1568627450980392
              roughness 1
              metalness 0
            }
            geometry Box {
              size 1 0.020000000000000004 0.019999999999999997
            }
          }
        ]
        name "pole"
        boundingObject USE POLE
        physics Physics {
          density -1
          mass 0.2
        }
      }
    }
  ]
  name "robot6"
  boundingObject USE BODY
  physics Physics {
    density -1
    mass 2
  }
  controller "robot_controller"
}
DEF ROBOT3 Robot {
  translation 1.21 0.045 -0.01
  rotation 0 0 -0.9999999999999978 0
  children [
    DEF EMITTER Emitter {
    }
    DEF RECEIVER Receiver {
    }
    DEF HINGE_COVER Solid {
      translation 0 0.03 -3.469446951953614e-18
      children [
        Shape {
          appearance PBRAppearance {
            baseColor 0 0.6509803921568628 1
          }
          geometry Box {
            size 0.030000000000000002 0.019999999999999997 0.05
          }
        }
      ]
      name "hingeCover"
    }
    DEF BODY Shape {
      appearance PBRAppearance {
        baseColor 0.917647 0.145098 0.145098
        roughness 1
        metalness 0
      }
      geometry Box {
        size 0.1 0.05 0.2
      }
    }
    DEF WHEEL1 HingeJoint {
      jointParameters HingeJointParameters {
        position 6.723540149111039e-17
        anchor 0.06 0 0.05
      }
      device [
        RotationalMotor {
          name "wheel1"
        }
      ]
      endPoint Solid {
        translation 0.06 0 0.05
        rotation 2.92596319263212e-14 -2.847458763273154e-14 1 1.5708000000006874
        children [
          DEF WHEEL Shape {
            appearance PBRAppearance {
              baseColor 0.305882 0.898039 0.25098
              roughness 1
              metalness 0
            }
            geometry Cylinder {
              height 0.02
              radius 0.04
              subdivision 24
            }
          }
        ]
        boundingObject USE WHEEL
        physics Physics {
        }
      }
    }
    DEF WHEEL2 HingeJoint {
      jointParameters HingeJointParameters {
        position 6.670640318240083e-17
        anchor -0.06 0 0.05
      }
      device [
        RotationalMotor {
          name "wheel2"
        }
      ]
      endPoint Solid {
        translation -0.06 0 0.05
        rotation 2.9494087369848315e-14 -2.8748295311748826e-14 1 1.5708000000006874
        children [
          USE WHEEL
        ]
        name "solid(1)"
        boundingObject USE WHEEL
        physics Physics {
        }
      }
    }
    DEF WHEEL3 HingeJoint {
      jointParameters HingeJointParameters {
        position 1.0324509589061627e-16
        anchor 0.06 0 -0.05
      }
      device [
        RotationalMotor {
          name "wheel3"
        }
      ]
      endPoint Solid {
        translation 0.06 0 -0.05
        rotation 4.412974529547543e-14 -4.326619678767453e-14 1 1.5708000000006896
        children [
          USE WHEEL
        ]
        name "solid(2)"
        boundingObject USE WHEEL
        physics Physics {
        }
      }
    }
    DEF WHEEL4 HingeJoint {
      jointParameters HingeJointParameters {
        position -2.6895122773572173e-17
        anchor -0.06 0 -0.05
      }
      device [
        RotationalMotor {
          name "wheel4"
        }
      ]
      endPoint Solid {
        translation -0.06 0 -0.05
        rotation -1.0808903637094097e-14 1.2496750127860889e-14 1 1.5708000000006894
        children [
          USE WHEEL
        ]
        name "solid(3)"
        boundingObject USE WHEEL
        physics Physics {
        }
      }
    }
    DEF POLE HingeJoint {
      jointParameters HingeJointParameters {
        position -4.812689688184746e-16
        anchor 0 0.03000000000047226 0
        minStop -1.3
        maxStop 1.3
      }
      device [
        DEF POLE_POS_SENSOR PositionSensor {
          name "polePosSensor"
        }
      ]
      endPoint Solid {
        translation -1.8379558561220506e-06 0.5299968874104792 -2.048272348424594e-13
        rotation -2.0444614298172612e-13 2.0546670474263567e-13 1 1.5708000033841252
        children [
          DEF POLE_ENDPOINT_3 Solid {
            translation 0.5000000000000002 0 0
            scale 0.1 0.1 0.1
            children [
              DEF BALL Shape {
                appearance PBRAppearance {
                  baseColor 0.03137254901960784 0.047058823529411764 1
                  metalness 0
                }
                geometry Sphere {
                  radius 0.1
                }
              }
            ]
            boundingObject USE BALL
            physics Physics {
              density -1
              mass 0.02
            }
          }
          DEF POLE Shape {
            appearance PBRAppearance {
              baseColor 1 0.1568627450980392 0.1568627450980392
              roughness 1
              metalness 0
            }
            geometry Box {
              size 1 0.020000000000000004 0.019999999999999997
            }
          }
        ]
        name "pole"
        boundingObject USE POLE
        physics Physics {
          density -1
          mass 0.2
        }
      }
    }
  ]
  name "robot3"
  boundingObject USE BODY
  physics Physics {
    density -1
    mass 2
  }
  controller "robot_controller"
}
DEF ROBOT0 Robot {
  translation 1.21 0.045 1.19
  rotation 0 0 -0.9999999999999978 0
  children [
    DEF EMITTER Emitter {
    }
    DEF RECEIVER Receiver {
    }
    DEF HINGE_COVER Solid {
      translation 0 0.03 -3.469446951953614e-18
      children [
        Shape {
          appearance PBRAppearance {
            baseColor 0 0.6509803921568628 1
          }
          geometry Box {
            size 0.030000000000000002 0.019999999999999997 0.05
          }
        }
      ]
      name "hingeCover"
    }
    DEF BODY Shape {
      appearance PBRAppearance {
        baseColor 0.917647 0.145098 0.145098
        roughness 1
        metalness 0
      }
      geometry Box {
        size 0.1 0.05 0.2
      }
    }
    DEF WHEEL1 HingeJoint {
      jointParameters HingeJointParameters {
        position 6.723540149111039e-17
        anchor 0.06 0 0.05
      }
      device [
        RotationalMotor {
          name "wheel1"
        }
      ]
      endPoint Solid {
        translation 0.06000000000000005 6.779894116991712e-18 0.050000000000000044
        rotation 2.2979273626099733e-14 -2.1958715896251777e-14 1 1.570800000000688
        children [
          DEF WHEEL Shape {
            appearance PBRAppearance {
              baseColor 0.305882 0.898039 0.25098
              roughness 1
              metalness 0
            }
            geometry Cylinder {
              height 0.02
              radius 0.04
              subdivision 24
            }
          }
        ]
        boundingObject USE WHEEL
        physics Physics {
        }
      }
    }
    DEF WHEEL2 HingeJoint {
      jointParameters HingeJointParameters {
        position 6.670640318240083e-17
        anchor -0.06 0 0.05
      }
      device [
        RotationalMotor {
          name "wheel2"
        }
      ]
      endPoint Solid {
        translation -0.06000000000000005 6.77989412148988e-18 0.050000000000000044
        rotation 2.1957657409582515e-14 -2.2114666857139845e-14 1 1.5708000000006916
        children [
          USE WHEEL
        ]
        name "solid(1)"
        boundingObject USE WHEEL
        physics Physics {
        }
      }
    }
    DEF WHEEL3 HingeJoint {
      jointParameters HingeJointParameters {
        position 1.0324509589061627e-16
        anchor 0.06 0 -0.05
      }
      device [
        RotationalMotor {
          name "wheel3"
        }
      ]
      endPoint Solid {
        translation 0.06000000000000005 -6.7798822651534035e-18 -0.050000000000000044
        rotation 3.435593769075574e-14 -3.4277433970482555e-14 1 1.5708000000006919
        children [
          USE WHEEL
        ]
        name "solid(2)"
        boundingObject USE WHEEL
        physics Physics {
        }
      }
    }
    DEF WHEEL4 HingeJoint {
      jointParameters HingeJointParameters {
        position -2.6895122773572173e-17
        anchor -0.06 0 -0.05
      }
      device [
        RotationalMotor {
          name "wheel4"
        }
      ]
      endPoint Solid {
        translation -0.06000000000000005 -6.779882283969024e-18 -0.050000000000000044
        rotation -7.825733444488926e-15 9.160309780868266e-15 1 1.570800000000685
        children [
          USE WHEEL
        ]
        name "solid(3)"
        boundingObject USE WHEEL
        physics Physics {
        }
      }
    }
    DEF POLE HingeJoint {
      jointParameters HingeJointParameters {
        position -4.812689688184746e-16
        anchor 0 0.03000000000047226 0
        minStop -1.3
        maxStop 1.3
      }
      device [
        DEF POLE_POS_SENSOR PositionSensor {
          name "polePosSensor"
        }
      ]
      endPoint Solid {
        translation -1.8379558146541657e-06 0.529996887410499 -1.6141751457961588e-13
        rotation -1.6026774763834265e-13 1.6093503924546247e-13 1 1.5708000033841285
        children [
          DEF POLE_ENDPOINT_0 Solid {
            translation 0.5000000000000002 0 0
            scale 0.1 0.1 0.1
            children [
              DEF BALL Shape {
                appearance PBRAppearance {
                  baseColor 0.03137254901960784 0.047058823529411764 1
                  metalness 0
                }
                geometry Sphere {
                  radius 0.1
                }
              }
            ]
            boundingObject USE BALL
            physics Physics {
              density -1
              mass 0.02
            }
          }
          DEF POLE Shape {
            appearance PBRAppearance {
              baseColor 1 0.1568627450980392 0.1568627450980392
              roughness 1
              metalness 0
            }
            geometry Box {
              size 1 0.020000000000000004 0.019999999999999997
            }
          }
        ]
        name "pole"
        boundingObject USE POLE
        physics Physics {
          density -1
          mass 0.2
        }
      }
    }
  ]
  name "robot0"
  boundingObject USE BODY
  physics Physics {
    density -1
    mass 2
  }
  controller "robot_controller"
}
DEF ROBOT1 Robot {
  translation 0.01 0.045 1.19
  rotation 0 0 -0.9999999999999978 0
  children [
    DEF EMITTER Emitter {
    }
    DEF RECEIVER Receiver {
    }
    DEF HINGE_COVER Solid {
      translation 0 0.03 -3.469446951953614e-18
      children [
        Shape {
          appearance PBRAppearance {
            baseColor 0 0.6509803921568628 1
          }
          geometry Box {
            size 0.030000000000000002 0.019999999999999997 0.05
          }
        }
      ]
      name "hingeCover"
    }
    DEF BODY Shape {
      appearance PBRAppearance {
        baseColor 0.917647 0.145098 0.145098
        roughness 1
        metalness 0
      }
      geometry Box {
        size 0.1 0.05 0.2
      }
    }
    DEF WHEEL1 HingeJoint {
      jointParameters HingeJointParameters {
        position 6.723540149111039e-17
        anchor 0.06 0 0.05
      }
      device [
        RotationalMotor {
          name "wheel1"
        }
      ]
      endPoint Solid {
        translation 0.06 0 0.05
        rotation 2.7748420710330397e-14 -2.859234435086068e-14 1 1.5708000000006888
        children [
          DEF WHEEL Shape {
            appearance PBRAppearance {
              baseColor 0.305882 0.898039 0.25098
              roughness 1
              metalness 0
            }
            geometry Cylinder {
              height 0.02
              radius 0.04
              subdivision 24
            }
          }
        ]
        boundingObject USE WHEEL
        physics Physics {
        }
      }
    }
    DEF WHEEL2 HingeJoint {
      jointParameters HingeJointParameters {
        position 6.670640318240083e-17
        anchor -0.06 0 0.05
      }
      device [
        RotationalMotor {
          name "wheel2"
        }
      ]
      endPoint Solid {
        translation -0.06 0 0.05
        rotation 2.7786614956975628e-14 -2.8944556508630773e-14 1 1.570800000000685
        children [
          USE WHEEL
        ]
        name "solid(1)"
        boundingObject USE WHEEL
        physics Physics {
        }
      }
    }
    DEF WHEEL3 HingeJoint {
      jointParameters HingeJointParameters {
        position 1.0324509589061627e-16
        anchor 0.06 0 -0.05
      }
      device [
        RotationalMotor {
          name "wheel3"
        }
      ]
      endPoint Solid {
        translation 0.06 0 -0.05
        rotation 4.4070866936410866e-14 -4.43848856099015e-14 1 1.5708000000006888
        children [
          USE WHEEL
        ]
        name "solid(2)"
        boundingObject USE WHEEL
        physics Physics {
        }
      }
    }
    DEF WHEEL4 HingeJoint {
      jointParameters HingeJointParameters {
        position -2.6895122773572173e-17
        anchor -0.06 0 -0.05
      }
      device [
        RotationalMotor {
          name "wheel4"
        }
      ]
      endPoint Solid {
        translation -0.06 0 -0.05
        rotation -1.0867781996158677e-14 1.200609713565609e-14 1 1.570800000000689
        children [
          USE WHEEL
        ]
        name "solid(3)"
        boundingObject USE WHEEL
        physics Physics {
        }
      }
    }
    DEF POLE HingeJoint {
      jointParameters HingeJointParameters {
        position -4.812689688184746e-16
        anchor 0 0.03000000000047226 0
        minStop -1.3
        maxStop 1.3
      }
      device [
        DEF POLE_POS_SENSOR PositionSensor {
          name "polePosSensor"
        }
      ]
      endPoint Solid {
        translation -1.8379558561220447e-06 0.5299968874104775 -2.0449416793507185e-13
        rotation -2.0452464746034593e-13 2.0515268682815572e-13 1 1.5708000033841265
        children [
          DEF POLE_ENDPOINT_1 Solid {
            translation 0.5000000000000002 0 0
            scale 0.1 0.1 0.1
            children [
              DEF BALL Shape {
                appearance PBRAppearance {
                  baseColor 0.03137254901960784 0.047058823529411764 1
                  metalness 0
                }
                geometry Sphere {
                  radius 0.1
                }
              }
            ]
            boundingObject USE BALL
            physics Physics {
              density -1
              mass 0.02
            }
          }
          DEF POLE Shape {
            appearance PBRAppearance {
              baseColor 1 0.1568627450980392 0.1568627450980392
              roughness 1
              metalness 0
            }
            geometry Box {
              size 1 0.020000000000000004 0.019999999999999997
            }
          }
        ]
        name "pole"
        boundingObject USE POLE
        physics Physics {
          density -1
          mass 0.2
        }
      }
    }
  ]
  name "robot1"
  boundingObject USE BODY
  physics Physics {
    density -1
    mass 2
  }
  controller "robot_controller"
}
DEF ROBOT2 Robot {
  translation -1.2 0.045 1.2
  rotation 0 0 -0.9999999999999978 0
  children [
    DEF EMITTER Emitter {
    }
    DEF RECEIVER Receiver {
    }
    DEF HINGE_COVER Solid {
      translation 0 0.03 -3.469446951953614e-18
      children [
        Shape {
          appearance PBRAppearance {
            baseColor 0 0.6509803921568628 1
          }
          geometry Box {
            size 0.030000000000000002 0.019999999999999997 0.05
          }
        }
      ]
      name "hingeCover"
    }
    DEF BODY Shape {
      appearance PBRAppearance {
        baseColor 0.917647 0.145098 0.145098
        roughness 1
        metalness 0
      }
      geometry Box {
        size 0.1 0.05 0.2
      }
    }
    DEF WHEEL1 HingeJoint {
      jointParameters HingeJointParameters {
        position 6.723540149111039e-17
        anchor 0.06 0 0.05
      }
      device [
        RotationalMotor {
          name "wheel1"
        }
      ]
      endPoint Solid {
        translation 0.06 0 0.05
        rotation 2.886710953255733e-14 -2.8160569717720452e-14 1 1.5708000000006888
        children [
          DEF WHEEL Shape {
            appearance PBRAppearance {
              baseColor 0.305882 0.898039 0.25098
              roughness 1
              metalness 0
            }
            geometry Cylinder {
              height 0.02
              radius 0.04
              subdivision 24
            }
          }
        ]
        boundingObject USE WHEEL
        physics Physics {
        }
      }
    }
    DEF WHEEL2 HingeJoint {
      jointParameters HingeJointParameters {
        position 6.670640318240083e-17
        anchor -0.06 0 0.05
      }
      device [
        RotationalMotor {
          name "wheel2"
        }
      ]
      endPoint Solid {
        translation -0.06 0 0.05
        rotation 2.7609979879781813e-14 -2.800250276359746e-14 1 1.5708000000006919
        children [
          USE WHEEL
        ]
        name "solid(1)"
        boundingObject USE WHEEL
        physics Physics {
        }
      }
    }
    DEF WHEEL3 HingeJoint {
      jointParameters HingeJointParameters {
        position 1.0324509589061627e-16
        anchor 0.06 0 -0.05
      }
      device [
        RotationalMotor {
          name "wheel3"
        }
      ]
      endPoint Solid {
        translation 0.06 0 -0.05
        rotation 4.3776475141087925e-14 -4.432600725083685e-14 1 1.5708000000006919
        children [
          USE WHEEL
        ]
        name "solid(2)"
        boundingObject USE WHEEL
        physics Physics {
        }
      }
    }
    DEF WHEEL4 HingeJoint {
      jointParameters HingeJointParameters {
        position -2.6895122773572173e-17
        anchor -0.06 0 -0.05
      }
      device [
        RotationalMotor {
          name "wheel4"
        }
      ]
      endPoint Solid {
        translation -0.06 0 -0.05
        rotation -1.0730399158341336e-14 1.0965912792181915e-14 1 1.5708000000006883
        children [
          USE WHEEL
        ]
        name "solid(3)"
        boundingObject USE WHEEL
        physics Physics {
        }
      }
    }
    DEF POLE HingeJoint {
      jointParameters HingeJointParameters {
        position -4.812689688184746e-16
        anchor 0 0.03000000000047226 0
        minStop -1.3
        maxStop 1.3
      }
      device [
        DEF POLE_POS_SENSOR PositionSensor {
          name "polePosSensor"
        }
      ]
      endPoint Solid {
        translation -1.837955856122051e-06 0.52999688741048 -2.0463294581315e-13
        rotation -2.0499567433206568e-13 2.049171733922958e-13 1 1.570800003384127
        children [
          DEF POLE_ENDPOINT_2 Solid {
            translation 0.5000000000000002 0 0
            scale 0.1 0.1 0.1
            children [
              DEF BALL Shape {
                appearance PBRAppearance {
                  baseColor 0.03137254901960784 0.047058823529411764 1
                  metalness 0
                }
                geometry Sphere {
                  radius 0.1
                }
              }
            ]
            boundingObject USE BALL
            physics Physics {
              density -1
              mass 0.02
            }
          }
          DEF POLE Shape {
            appearance PBRAppearance {
              baseColor 1 0.1568627450980392 0.1568627450980392
              roughness 1
              metalness 0
            }
            geometry Box {
              size 1 0.020000000000000004 0.019999999999999997
            }
          }
        ]
        name "pole"
        boundingObject USE POLE
        physics Physics {
          density -1
          mass 0.2
        }
      }
    }
  ]
  name "robot2"
  boundingObject USE BODY
  physics Physics {
    density -1
    mass 2
  }
  controller "robot_controller"
}
SolidBox {
  translation 1.6 0.1 -0.6
  name "box(30)"
  size 0.2 0.2 0.2
}
SolidBox {
  translation 1.4 0.1 -0.6
  name "box(31)"
  size 0.2 0.2 0.2
}
SolidBox {
  translation 1.2 0.1 -0.6
  name "box(32)"
  size 0.2 0.2 0.2
}
SolidBox {
  translation 1 0.1 -0.6
  name "box(33)"
  size 0.2 0.2 0.2
}
SolidBox {
  translation 0.8 0.1 -0.6
  name "box(34)"
  size 0.2 0.2 0.2
}
SolidBox {
  translation 0.6 0.1 -0.6
  name "box(35)"
  size 0.2 0.2 0.2
}
SolidBox {
  translation 0.6 0.1 -0.8
  name "box(41)"
  size 0.2 0.2 0.2
}
SolidBox {
  translation 0.6 0.1 -1
  name "box(42)"
  size 0.2 0.2 0.2
}
SolidBox {
  translation 0.6 0.1 -1.2
  name "box(43)"
  size 0.2 0.2 0.2
}
SolidBox {
  translation 0.6 0.1 -1.4
  name "box(44)"
  size 0.2 0.2 0.2
}
SolidBox {
  translation 0.6 0.1 -1.6
  name "box(45)"
  size 0.2 0.2 0.2
}
SolidBox {
  translation 0.6 0.1 -0.4
  name "box(36)"
  size 0.2 0.2 0.2
}
SolidBox {
  translation 0.6 0.1 -0.2
  name "box(37)"
  size 0.2 0.2 0.2
}
SolidBox {
  translation 0.6 0.1 0
  name "box(38)"
  size 0.2 0.2 0.2
}
SolidBox {
  translation 0.6 0.1 0.2
  name "box(39)"
  size 0.2 0.2 0.2
}
SolidBox {
  translation 0.6 0.1 0.4
  name "box(40)"
  size 0.2 0.2 0.2
}
SolidBox {
  translation 1.6 0.1 0.6
  name "box(12)"
  size 0.2 0.2 0.2
}
SolidBox {
  translation -0.6 0.1 1.6
  name "box(64)"
  size 0.2 0.2 0.2
}
SolidBox {
  translation -0.6 0.1 1.4
  name "box(65)"
  size 0.2 0.2 0.2
}
SolidBox {
  translation -0.6 0.1 1.2
  name "box(66)"
  size 0.2 0.2 0.2
}
SolidBox {
  translation -0.6 0.1 1
  name "box(67)"
  size 0.2 0.2 0.2
}
SolidBox {
  translation -0.6 0.1 0.8
  name "box(68)"
  size 0.2 0.2 0.2
}
SolidBox {
  translation -0.6 0.1 0.6
  name "box(69)"
  size 0.2 0.2 0.2
}
SolidBox {
  translation -0.6 0.1 0.4
  name "box(75)"
  size 0.2 0.2 0.2
}
SolidBox {
  translation -0.6 0.1 0.2
  name "box(76)"
  size 0.2 0.2 0.2
}
SolidBox {
  translation -0.6 0.1 0
  name "box(77)"
  size 0.2 0.2 0.2
}
SolidBox {
  translation -0.6 0.1 -0.2
  name "box(78)"
  size 0.2 0.2 0.2
}
SolidBox {
  translation -0.6 0.1 -0.4
  name "box(79)"
  size 0.2 0.2 0.2
}
SolidBox {
  translation -0.6 0.1 -0.6
  name "box(80)"
  size 0.2 0.2 0.2
}
SolidBox {
  translation -0.6 0.1 -0.8
  name "box(86)"
  size 0.2 0.2 0.2
}
SolidBox {
  translation -0.6 0.1 -1
  name "box(87)"
  size 0.2 0.2 0.2
}
SolidBox {
  translation -0.6 0.1 -1.2
  name "box(88)"
  size 0.2 0.2 0.2
}
SolidBox {
  translation -0.6 0.1 -1.4
  name "box(89)"
  size 0.2 0.2 0.2
}
SolidBox {
  translation -0.6 0.1 -1.6
  name "box(90)"
  size 0.2 0.2 0.2
}
SolidBox {
  translation -1.6 0.1 -0.6
  name "box(109)"
  size 0.2 0.2 0.2
}
SolidBox {
  translation -1.4 0.1 -0.6
  name "box(111)"
  size 0.2 0.2 0.2
}
SolidBox {
  translation -1.2 0.1 -0.6
  name "box(112)"
  size 0.2 0.2 0.2
}
SolidBox {
  translation -1 0.1 -0.6
  name "box(113)"
  size 0.2 0.2 0.2
}
SolidBox {
  translation -0.8 0.1 -0.6
  name "box(114)"
  size 0.2 0.2 0.2
}
SolidBox {
  translation -1.6 0.1 0.6
  name "box(121)"
  size 0.2 0.2 0.2
}
SolidBox {
  translation -1.4 0.1 0.6
  name "box(122)"
  size 0.2 0.2 0.2
}
SolidBox {
  translation -1.2 0.1 0.6
  name "box(123)"
  size 0.2 0.2 0.2
}
SolidBox {
  translation -1 0.1 0.6
  name "box(124)"
  size 0.2 0.2 0.2
}
SolidBox {
  translation -0.8 0.1 0.6
  name "box(125)"
  size 0.2 0.2 0.2
}
SolidBox {
  translation -0.4 0.1 -0.6
  name "box(81)"
  size 0.2 0.2 0.2
}
SolidBox {
  translation -0.2 0.1 -0.6
  name "box(82)"
  size 0.2 0.2 0.2
}
SolidBox {
  translation 0 0.1 -0.6
  name "box(83)"
  size 0.2 0.2 0.2
}
SolidBox {
  translation 0.2 0.1 -0.6
  name "box(84)"
  size 0.2 0.2 0.2
}
SolidBox {
  translation 0.4 0.1 -0.6
  name "box(85)"
  size 0.2 0.2 0.2
}
SolidBox {
  translation -0.4 0.1 0.6
  name "box(70)"
  size 0.2 0.2 0.2
}
SolidBox {
  translation -0.2 0.1 0.6
  name "box(71)"
  size 0.2 0.2 0.2
}
SolidBox {
  translation 0 0.1 0.6
  name "box(72)"
  size 0.2 0.2 0.2
}
SolidBox {
  translation 0.2 0.1 0.6
  name "box(73)"
  size 0.2 0.2 0.2
}
SolidBox {
  translation 0.4 0.1 0.6
  name "box(74)"
  size 0.2 0.2 0.2
}
SolidBox {
  translation 0.6 0.1 1.6
  name "box(15)"
  size 0.2 0.2 0.2
}
SolidBox {
  translation 0.6 0.1 1.4
  name "box(16)"
  size 0.2 0.2 0.2
}
SolidBox {
  translation 0.6 0.1 1.2
  name "box(17)"
  size 0.2 0.2 0.2
}
SolidBox {
  translation 0.6 0.1 1
  name "box(18)"
  size 0.2 0.2 0.2
}
SolidBox {
  translation 0.6 0.1 0.8
  name "box(19)"
  size 0.2 0.2 0.2
}
SolidBox {
  translation 0.6 0.1 0.6
  name "box(20)"
  size 0.2 0.2 0.2
}
SolidBox {
  translation 1.4 0.1 0.6
  name "box(21)"
  size 0.2 0.2 0.2
}
SolidBox {
  translation 1.2 0.1 0.6
  name "box(22)"
  size 0.2 0.2 0.2
}
SolidBox {
  translation 1 0.1 0.6
  name "box(23)"
  size 0.2 0.2 0.2
}
SolidBox {
  translation 0.8 0.1 0.6
  name "box(24)"
  size 0.2 0.2 0.2
}
