<robot name="test_robot">
    <link name="base_link">
    </link>
    <link name="link_1">
    </link>
    <joint name="joint_1" type="revolute">
        <origin
            xyz="0 0 0.141"
            rpy="0 0 0" />
        <parent link="base_link" />
        <child link="link_1" />
        <axis xyz="0 0 1" />
		<limit effort="87" lower="-2.8973" upper="2.8973" velocity="2.1750"/>
    </joint>
    
    <link name="link_2">
    </link>
    <joint name="joint_2" type="revolute">
        <origin
            xyz="0 0 0.192"
            rpy="-1.5708 0 0" />
        <parent link="link_1" />
        <child link="link_2" />
        <axis xyz="0 0 1" />
        <limit effort="87" lower="-1.7628" upper="1.7628" velocity="2.1750"/>
    </joint>
    
    <link name="link_3">
    </link>
    <joint name="joint_3" type="revolute">
        <origin
            xyz="0 -0.195 0"
            rpy="1.5708 0 0" />
        <parent link="link_2" />
        <child link="link_3" />
        <axis xyz="0 0 1" />
        <limit effort="87" lower="-2.8973" upper="2.8973" velocity="2.1750"/>
    </joint>
    
    <link name="link_4">
    </link>
    <joint name="joint_4" type="revolute">
        <origin
            xyz="0.0825 0 0.124"
            rpy="1.5708 0 0" />
        <parent link="link_3" />
        <child link="link_4" />
        <axis xyz="0 0 1" />
        <limit effort="87" lower="-3.0718" upper="-0.0698" velocity="2.1750"/>
    </joint>
    
    <link name="link_5">
    </link>
    <joint name="joint_5" type="revolute">
        <origin
            xyz="-0.0825 0.122 0"
            rpy="-1.5708 0 0" />
        <parent link="link_4" />
        <child link="link_5" />
        <axis xyz="0 0 1" />
        <limit effort="12" lower="-2.8973" upper="2.8973" velocity="2.6100"/>
    </joint>
    
    <link name="link_6">
    </link>
    <joint name="joint_6" type="revolute">
        <origin
            xyz="0 0 0.259"
            rpy="1.5708 0 0" />
        <parent link="link_5" />
        <child link="link_6" />
        <axis xyz="0 0 1" />
        <limit effort="12" lower="-0.0175" upper="3.7525" velocity="2.6100"/>
    </joint>
    

    <link name="link_7n8">
    </link>
    <joint name="joint_7n8" type="revolute">
        <origin
            xyz="0.088 -0.107 0"
            rpy="1.5708 0 0" />
        <parent link="link_6" />
        <child link="link_7n8" />
        <axis xyz="0 0 1" />
        <limit effort="12" lower="-2.8973" upper="2.8973" velocity="2.6100"/>
    </joint>
    <link name="link_finger_center">
    </link>
    <joint name="joint_finger_center" type="fixed">
        <origin
            xyz="0 0 0.1034"
            rpy="0 0 0" />
        <parent link="link_7n8" />
        <child link="link_finger_center" />
    </joint>
</robot>