#VRML_SIM R2023b utf8

EXTERNPROTO "https://raw.githubusercontent.com/cyberbotics/webots/R2023a/projects/objects/backgrounds/protos/TexturedBackground.proto"
EXTERNPROTO "https://raw.githubusercontent.com/cyberbotics/webots/R2023a/projects/objects/backgrounds/protos/TexturedBackgroundLight.proto"
EXTERNPROTO "https://raw.githubusercontent.com/cyberbotics/webots/R2023a/projects/objects/floors/protos/RectangleArena.proto"

WorldInfo {
}
Viewpoint {
  orientation -0.2245453396718058 0.22010075965534806 0.9492813313400891 1.6427889618378544
  position 0.15724478105920425 -5.395156343003796 3.534108418869838
}
TexturedBackground {
}
TexturedBackgroundLight {
}
RectangleArena {
  floorSize 2 1
}
DEF ROBOT1 Robot {
  translation -0.175 0 0.04
  rotation 1 0 0 1.5708
  children [
    DEF HINGE_COVER Solid {
      translation 0 0.03 -3.469446951953614e-18
      rotation 0 1 0 -1.5707953071795862
      children [
        Shape {
          appearance PBRAppearance {
            baseColor 0 0.6509803921568628 1
          }
          geometry Box {
            size 0.030000000000000002 0.019999999999999997 0.05
          }
        }
      ]
      name "hingeCover"
    }
    DEF BODY Shape {
      appearance PBRAppearance {
        baseColor 0.917647 0.145098 0.145098
        roughness 1
        metalness 0
      }
      geometry Box {
        size 0.2 0.05 0.08
      }
    }
    DEF WHEEL1 HingeJoint {
      jointParameters HingeJointParameters {
        position 6.723540149111039e-17
        axis 0 0 1
        anchor 0.06 0 0.05
      }
      device [
        RotationalMotor {
          name "wheel1"
        }
      ]
      endPoint Solid {
        translation 0.060001004644818584 1.339276918416963e-05 0.050000010543824816
        rotation 1.7671082538995992e-08 -1.7671248834016876e-08 0.9999999999999998 1.5708000430119498
        children [
          DEF WHEEL Shape {
            appearance PBRAppearance {
              baseColor 0.305882 0.898039 0.25098
              roughness 1
              metalness 0
            }
            geometry Cylinder {
              height 0.02
              radius 0.04
              subdivision 24
            }
          }
        ]
        boundingObject USE WHEEL
        physics Physics {
        }
      }
    }
    DEF WHEEL2 HingeJoint {
      jointParameters HingeJointParameters {
        position 6.670640318240083e-17
        axis 0 0 1
        anchor -0.06 0 0.05
      }
      device [
        RotationalMotor {
          name "wheel2"
        }
      ]
      endPoint Solid {
        translation -0.060001095993954395 7.6163387232517e-07 0.05000000952472374
        rotation 1.76096540431902e-08 -1.7609826183889808e-08 0.9999999999999997 1.5707999569897093
        children [
          USE WHEEL
        ]
        name "solid(1)"
        boundingObject USE WHEEL
        physics Physics {
        }
      }
    }
    DEF WHEEL3 HingeJoint {
      jointParameters HingeJointParameters {
        position 1.0324509589061627e-16
        axis 0 0 1
        anchor 0.06 0 -0.05
      }
      device [
        RotationalMotor {
          name "wheel3"
        }
      ]
      endPoint Solid {
        translation 0.06000100379909951 1.3392659934531687e-05 -0.05000000738328558
        rotation -1.7671380018270767e-08 1.7671539284228046e-08 0.9999999999999998 1.5708000430119113
        children [
          USE WHEEL
        ]
        name "solid(2)"
        boundingObject USE WHEEL
        physics Physics {
        }
      }
    }
    DEF WHEEL4 HingeJoint {
      jointParameters HingeJointParameters {
        position -2.6895122773572173e-17
        axis 0 0 1
        anchor -0.06 0 -0.05
      }
      device [
        RotationalMotor {
          name "wheel4"
        }
      ]
      endPoint Solid {
        translation -0.060001096839924606 7.615246225854488e-07 -0.05000000839401549
        rotation -1.761000837263908e-08 1.761018020913388e-08 0.9999999999999997 1.5707999569897055
        children [
          USE WHEEL
        ]
        name "solid(3)"
        boundingObject USE WHEEL
        physics Physics {
        }
      }
    }
    DEF POLE HingeJoint {
      jointParameters HingeJointParameters {
        position -4.812689688184746e-16
        axis 0 0 1
        anchor 0 0.03000000000047226 0
        minStop -1.3
        maxStop 1.3
      }
      device [
        DEF POLE_POS_SENSOR PositionSensor {
          name "polePosSensor"
        }
      ]
      endPoint Solid {
        translation -0.0004655326854935488 0.5300037594690288 -5.369584240411801e-07
        rotation -0.5769874410964125 -0.5775313877690027 0.577531807746226 2.0949379676602047
        children [
          DEF POLE_ENDPOINT Solid {
            translation 0.5000000000000002 0 0
            children [
              DEF BALL Shape {
                appearance PBRAppearance {
                  baseColor 0.03137254901960784 0.047058823529411764 1
                  metalness 0
                }
                geometry Sphere {
                  radius 0.01
                }
              }
            ]
            boundingObject USE BALL
            physics Physics {
              density -1
              mass 0.02
            }
          }
          DEF POLE Shape {
            appearance PBRAppearance {
              baseColor 1 0.1568627450980392 0.1568627450980392
              roughness 1
              metalness 0
            }
            geometry Box {
              size 1 0.020000000000000004 0.019999999999999997
            }
          }
          DEF CONNECTOR_HINGE HingeJoint {
            jointParameters HingeJointParameters {
              axis 0 1 0
              anchor 0.4925 0 -0.0099993
            }
            endPoint DEF CONNECTION_POLE Solid {
              translation 0.4925 0 -0.091
              rotation 0 1 0 1.5708
              children [
                DEF MIDDLE_CONNECTOR_HINGE HingeJoint {
                  jointParameters HingeJointParameters {
                    axis 0 1 0
                    anchor 0.085 0 0
                  }
                  endPoint Solid {
                    translation 0.085 0 0.51
                    rotation 0 -0.9999999999999999 0 1.5707953071795862
                    children [
                      DEF MIDDLE_POLE Shape {
                        appearance PBRAppearance {
                          baseColor 0.305882 0.898039 0.25098
                          metalness 0
                        }
                        geometry Box {
                          size 1 0.020000000000000004 0.019999999999999997
                        }
                      }
                    ]
                    boundingObject USE MIDDLE_POLE
                    physics Physics {
                    }
                  }
                }
                DEF CONNECTING_POLE Shape {
                  appearance PBRAppearance {
                    baseColor 1 0.1568627450980392 0.1568627450980392
                    roughness 1
                    metalness 0
                  }
                  geometry Box {
                    size 0.17 0.02 0.02
                  }
                }
                Connector {
                  translation 0.085 0 0
                  rotation 0 1 0 0
                  isLocked TRUE
                  autoLock TRUE
                }
              ]
              name "solid(4)"
              boundingObject USE CONNECTING_POLE
              physics Physics {
              }
            }
          }
        ]
        name "pole"
        boundingObject USE POLE
        physics Physics {
          density -1
          mass 0.2
        }
      }
    }
  ]
  name "robot1"
  boundingObject USE BODY
  physics Physics {
    density -1
    mass 2
  }
  controller ""
  supervisor TRUE
}
DEF ROBOT2 Robot {
  translation 0.175 0 0.04
  rotation 1 0 0 1.5708
  children [
    DEF HINGE_COVER Solid {
      translation 0 0.03 -3.469446951953614e-18
      rotation 0 1 0 -1.5707953071795862
      children [
        Shape {
          appearance PBRAppearance {
            baseColor 0 0.6509803921568628 1
          }
          geometry Box {
            size 0.030000000000000002 0.019999999999999997 0.05
          }
        }
      ]
      name "hingeCover"
    }
    DEF BODY Shape {
      appearance PBRAppearance {
        baseColor 0.917647 0.145098 0.145098
        roughness 1
        metalness 0
      }
      geometry Box {
        size 0.2 0.05 0.08
      }
    }
    DEF WHEEL1 HingeJoint {
      jointParameters HingeJointParameters {
        position 6.723540149111039e-17
        axis 0 0 1
        anchor 0.06 0 0.05
      }
      device [
        RotationalMotor {
          name "wheel1"
        }
      ]
      endPoint Solid {
        translation 0.060001004644818584 1.339276918416963e-05 0.050000010543824816
        rotation 1.7671082538995992e-08 -1.7671248834016876e-08 0.9999999999999998 1.5708000430119498
        children [
          DEF WHEEL Shape {
            appearance PBRAppearance {
              baseColor 0.305882 0.898039 0.25098
              roughness 1
              metalness 0
            }
            geometry Cylinder {
              height 0.02
              radius 0.04
              subdivision 24
            }
          }
        ]
        boundingObject USE WHEEL
        physics Physics {
        }
      }
    }
    DEF WHEEL2 HingeJoint {
      jointParameters HingeJointParameters {
        position 6.670640318240083e-17
        axis 0 0 1
        anchor -0.06 0 0.05
      }
      device [
        RotationalMotor {
          name "wheel2"
        }
      ]
      endPoint Solid {
        translation -0.060001095993954395 7.6163387232517e-07 0.05000000952472374
        rotation 1.76096540431902e-08 -1.7609826183889808e-08 0.9999999999999997 1.5707999569897093
        children [
          USE WHEEL
        ]
        name "solid(1)"
        boundingObject USE WHEEL
        physics Physics {
        }
      }
    }
    DEF WHEEL3 HingeJoint {
      jointParameters HingeJointParameters {
        position 1.0324509589061627e-16
        axis 0 0 1
        anchor 0.06 0 -0.05
      }
      device [
        RotationalMotor {
          name "wheel3"
        }
      ]
      endPoint Solid {
        translation 0.06000100379909951 1.3392659934531687e-05 -0.05000000738328558
        rotation -1.7671380018270767e-08 1.7671539284228046e-08 0.9999999999999998 1.5708000430119113
        children [
          USE WHEEL
        ]
        name "solid(2)"
        boundingObject USE WHEEL
        physics Physics {
        }
      }
    }
    DEF WHEEL4 HingeJoint {
      jointParameters HingeJointParameters {
        position -2.6895122773572173e-17
        axis 0 0 1
        anchor -0.06 0 -0.05
      }
      device [
        RotationalMotor {
          name "wheel4"
        }
      ]
      endPoint Solid {
        translation -0.060001096839924606 7.615246225854488e-07 -0.05000000839401549
        rotation -1.761000837263908e-08 1.761018020913388e-08 0.9999999999999997 1.5707999569897055
        children [
          USE WHEEL
        ]
        name "solid(3)"
        boundingObject USE WHEEL
        physics Physics {
        }
      }
    }
    DEF POLE HingeJoint {
      jointParameters HingeJointParameters {
        position -4.812689688184746e-16
        axis 0 0 1
        anchor 0 0.03000000000047226 0
        minStop -1.3
        maxStop 1.3
      }
      device [
        DEF POLE_POS_SENSOR PositionSensor {
          name "polePosSensor"
        }
      ]
      endPoint Solid {
        translation -0.0004655326854935488 0.5300037594690288 -5.369584240411801e-07
        rotation -0.5769874410964125 -0.5775313877690027 0.577531807746226 2.0949379676602047
        children [
          DEF POLE_ENDPOINT Solid {
            translation 0.5000000000000002 0 0
            children [
              DEF BALL Shape {
                appearance PBRAppearance {
                  baseColor 0.03137254901960784 0.047058823529411764 1
                  metalness 0
                }
                geometry Sphere {
                  radius 0.01
                }
              }
            ]
            boundingObject USE BALL
            physics Physics {
              density -1
              mass 0.02
            }
          }
          DEF POLE Shape {
            appearance PBRAppearance {
              baseColor 1 0.1568627450980392 0.1568627450980392
              roughness 1
              metalness 0
            }
            geometry Box {
              size 1 0.020000000000000004 0.019999999999999997
            }
          }
          DEF CONNECTOR_HINGE HingeJoint {
            jointParameters HingeJointParameters {
              axis 0 1 0
              anchor 0.4925 0 0.0099993
            }
            endPoint DEF CONNECTION_POLE Solid {
              translation 0.4925 0 0.091
              rotation 0 1 0 1.5708
              children [
                DEF CONNECTIONG_POLE Shape {
                  appearance PBRAppearance {
                    baseColor 1 0.1568627450980392 0.1568627450980392
                    roughness 1
                    metalness 0
                  }
                  geometry Box {
                    size 0.17 0.02 0.02
                  }
                }
                Connector {
                  translation -0.085 0 0
                  rotation 0 1 0 3.14159
                  isLocked TRUE
                  autoLock TRUE
                }
              ]
              name "solid(4)"
              boundingObject USE CONNECTIONG_POLE
              physics Physics {
              }
            }
          }
        ]
        name "pole"
        boundingObject USE POLE
        physics Physics {
          density -1
          mass 0.2
        }
      }
    }
  ]
  name "robot2"
  boundingObject USE BODY
  physics Physics {
    density -1
    mass 2
  }
  controller ""
  supervisor TRUE
}
