#VRML_SIM R2023b utf8

EXTERNPROTO "https://raw.githubusercontent.com/cyberbotics/webots/R2023a/projects/objects/backgrounds/protos/TexturedBackground.proto"
EXTERNPROTO "https://raw.githubusercontent.com/cyberbotics/webots/R2023a/projects/objects/backgrounds/protos/TexturedBackgroundLight.proto"
EXTERNPROTO "https://raw.githubusercontent.com/cyberbotics/webots/R2023a/projects/objects/floors/protos/RectangleArena.proto"

WorldInfo {
}
Viewpoint {
  orientation -0.22438816324297137 0.18581999328958307 0.9566195075840263 1.8016787924741189
  position 0.970011609840356 -5.281963045756185 2.9764464701238467
}
TexturedBackground {
}
TexturedBackgroundLight {
}
RectangleArena {
  floorSize 2 1
}
DEF ROBOT1 Robot {
  translation -0.175 0 0.04
  rotation 1 0 0 1.5708
  children [
    Receiver {
      channel 1
    }
    Emitter {
      channel 1
    }
    DEF HINGE_COVER Solid {
      translation 0 0.03 -3.469446951953614e-18
      rotation 0 1 0 -1.5707953071795862
      children [
        Shape {
          appearance PBRAppearance {
            baseColor 0 0.6509803921568628 1
          }
          geometry Box {
            size 0.030000000000000002 0.019999999999999997 0.05
          }
        }
      ]
      name "hingeCover"
    }
    DEF BODY Shape {
      appearance PBRAppearance {
        baseColor 0.917647 0.145098 0.145098
        roughness 1
        metalness 0
      }
      geometry Box {
        size 0.2 0.05 0.08
      }
    }
    DEF WHEEL1 HingeJoint {
      jointParameters HingeJointParameters {
        position 6.723540149111039e-17
        axis 0 0 1
        anchor 0.06 0 0.05
      }
      device [
        RotationalMotor {
          name "wheel1"
        }
      ]
      endPoint Solid {
        translation 0.060001004644818584 1.3392769184156323e-05 0.050000010543824816
        rotation 1.7671082538981295e-08 -1.767124883400224e-08 0.9999999999999998 1.5708000430119768
        children [
          DEF WHEEL Shape {
            appearance PBRAppearance {
              baseColor 0.305882 0.898039 0.25098
              roughness 1
              metalness 0
            }
            geometry Cylinder {
              height 0.02
              radius 0.04
              subdivision 24
            }
          }
        ]
        boundingObject USE WHEEL
        physics Physics {
        }
      }
    }
    DEF WHEEL2 HingeJoint {
      jointParameters HingeJointParameters {
        position 6.670640318240083e-17
        axis 0 0 1
        anchor -0.06 0 0.05
      }
      device [
        RotationalMotor {
          name "wheel2"
        }
      ]
      endPoint Solid {
        translation -0.060001095993954395 7.616338723237992e-07 0.05000000952472374
        rotation 1.7609654043176984e-08 -1.760982618387657e-08 0.9999999999999997 1.5707999569897166
        children [
          USE WHEEL
        ]
        name "solid(1)"
        boundingObject USE WHEEL
        physics Physics {
        }
      }
    }
    DEF WHEEL3 HingeJoint {
      jointParameters HingeJointParameters {
        position 1.0324509589061627e-16
        axis 0 0 1
        anchor 0.06 0 -0.05
      }
      device [
        RotationalMotor {
          name "wheel3"
        }
      ]
      endPoint Solid {
        translation 0.06000100379909951 1.3392659934541313e-05 -0.05000000738328558
        rotation -1.7671380018249366e-08 1.7671539284206642e-08 0.9999999999999998 1.5708000430119422
        children [
          USE WHEEL
        ]
        name "solid(2)"
        boundingObject USE WHEEL
        physics Physics {
        }
      }
    }
    DEF WHEEL4 HingeJoint {
      jointParameters HingeJointParameters {
        position -2.6895122773572173e-17
        axis 0 0 1
        anchor -0.06 0 -0.05
      }
      device [
        RotationalMotor {
          name "wheel4"
        }
      ]
      endPoint Solid {
        translation -0.060001096839924606 7.615246225931939e-07 -0.05000000839401549
        rotation -1.761000837262806e-08 1.7610180209122837e-08 0.9999999999999997 1.570799956989715
        children [
          USE WHEEL
        ]
        name "solid(3)"
        boundingObject USE WHEEL
        physics Physics {
        }
      }
    }
    DEF POLE HingeJoint {
      jointParameters HingeJointParameters {
        position -4.812689688184746e-16
        axis 0 0 1
        anchor 0 0.03000000000047226 0
        minStop -1.3
        maxStop 1.3
      }
      device [
        DEF POLE_POS_SENSOR PositionSensor {
          name "polePosSensor"
        }
      ]
      endPoint Solid {
        translation -0.00046553268547138316 0.5300037594690259 -5.369584240411779e-07
        rotation -0.5769874410964262 -0.5775313877689972 0.5775318077462179 2.094937967660199
        children [
          DEF POLE_ENDPOINT_1 Solid {
            translation 0.5000000000000002 0 0
            children [
              DEF BALL Shape {
                appearance PBRAppearance {
                  baseColor 0.03137254901960784 0.047058823529411764 1
                  metalness 0
                }
                geometry Sphere {
                  radius 0.01
                }
              }
            ]
            boundingObject USE BALL
            physics Physics {
              density -1
              mass 0.02
            }
          }
          DEF POLE Shape {
            appearance PBRAppearance {
              baseColor 1 0.1568627450980392 0.1568627450980392
              roughness 1
              metalness 0
            }
            geometry Box {
              size 1 0.020000000000000004 0.019999999999999997
            }
          }
          DEF CONNECTOR_HINGE HingeJoint {
            jointParameters HingeJointParameters {
              axis 0 1 0
              anchor 0.4925 0 -0.0099993
            }
            endPoint DEF CONNECTION_POLE Solid {
              translation 0.49249999999999994 0 -0.09099999999999987
              rotation 0 1 0 1.5707999999999929
              children [
                DEF CONNECTIONG_POLE Shape {
                  appearance PBRAppearance {
                    baseColor 1 0.1568627450980392 0.1568627450980392
                    roughness 1
                    metalness 0
                  }
                  geometry Box {
                    size 0.17 0.02 0.02
                  }
                }
                Connector {
                  translation 0.085 0 0
                  rotation 0 1 0 0
                  isLocked TRUE
                  autoLock TRUE
                }
              ]
              name "solid(4)"
              boundingObject USE CONNECTIONG_POLE
              physics Physics {
              }
            }
          }
        ]
        name "pole"
        boundingObject USE POLE
        physics Physics {
          density -1
          mass 0.2
        }
      }
    }
  ]
  name "robot1"
  boundingObject USE BODY
  physics Physics {
    density -1
    mass 2
  }
  controller "robot_controller"
  supervisor TRUE
}
DEF ROBOT2 Robot {
  translation 0.175 0 0.04
  rotation 1 0 0 1.5708
  children [
    Receiver {
      channel 2
    }
    Emitter {
      channel 2
    }
    DEF HINGE_COVER Solid {
      translation 0 0.03 -3.469446951953614e-18
      rotation 0 1 0 -1.5707953071795862
      children [
        Shape {
          appearance PBRAppearance {
            baseColor 0 0.6509803921568628 1
          }
          geometry Box {
            size 0.030000000000000002 0.019999999999999997 0.05
          }
        }
      ]
      name "hingeCover"
    }
    DEF BODY Shape {
      appearance PBRAppearance {
        baseColor 0.917647 0.145098 0.145098
        roughness 1
        metalness 0
      }
      geometry Box {
        size 0.2 0.05 0.08
      }
    }
    DEF WHEEL1 HingeJoint {
      jointParameters HingeJointParameters {
        position 6.723540149111039e-17
        axis 0 0 1
        anchor 0.06 0 0.05
      }
      device [
        RotationalMotor {
          name "wheel1"
        }
      ]
      endPoint Solid {
        translation 0.060001004644818584 1.339276918415257e-05 0.050000010543824816
        rotation 1.767108253898783e-08 -1.767124883400869e-08 0.9999999999999998 1.5708000430119542
        children [
          DEF WHEEL Shape {
            appearance PBRAppearance {
              baseColor 0.305882 0.898039 0.25098
              roughness 1
              metalness 0
            }
            geometry Cylinder {
              height 0.02
              radius 0.04
              subdivision 24
            }
          }
        ]
        boundingObject USE WHEEL
        physics Physics {
        }
      }
    }
    DEF WHEEL2 HingeJoint {
      jointParameters HingeJointParameters {
        position 6.670640318240083e-17
        axis 0 0 1
        anchor -0.06 0 0.05
      }
      device [
        RotationalMotor {
          name "wheel2"
        }
      ]
      endPoint Solid {
        translation -0.060001095993954395 7.616338723367299e-07 0.05000000952472374
        rotation 1.7609654043185626e-08 -1.7609826183885216e-08 0.9999999999999997 1.5707999569897144
        children [
          USE WHEEL
        ]
        name "solid(1)"
        boundingObject USE WHEEL
        physics Physics {
        }
      }
    }
    DEF WHEEL3 HingeJoint {
      jointParameters HingeJointParameters {
        position 1.0324509589061627e-16
        axis 0 0 1
        anchor 0.06 0 -0.05
      }
      device [
        RotationalMotor {
          name "wheel3"
        }
      ]
      endPoint Solid {
        translation 0.06000100379909951 1.3392659934548092e-05 -0.05000000738328558
        rotation -1.7671380018269606e-08 1.7671539284226908e-08 0.9999999999999998 1.5708000430119105
        children [
          USE WHEEL
        ]
        name "solid(2)"
        boundingObject USE WHEEL
        physics Physics {
        }
      }
    }
    DEF WHEEL4 HingeJoint {
      jointParameters HingeJointParameters {
        position -2.6895122773572173e-17
        axis 0 0 1
        anchor -0.06 0 -0.05
      }
      device [
        RotationalMotor {
          name "wheel4"
        }
      ]
      endPoint Solid {
        translation -0.060001096839924606 7.615246225906312e-07 -0.05000000839401549
        rotation -1.7610008372633182e-08 1.761018020912797e-08 0.9999999999999997 1.570799956989704
        children [
          USE WHEEL
        ]
        name "solid(3)"
        boundingObject USE WHEEL
        physics Physics {
        }
      }
    }
    DEF POLE HingeJoint {
      jointParameters HingeJointParameters {
        position -4.812689688184746e-16
        axis 0 0 1
        anchor 0 0.03000000000047226 0
        minStop -1.3
        maxStop 1.3
      }
      device [
        DEF POLE_POS_SENSOR PositionSensor {
          name "polePosSensor"
        }
      ]
      endPoint Solid {
        translation -0.0004655326854714942 0.5300037594690241 -5.369584240411765e-07
        rotation -0.5769874410964244 -0.5775313877689967 0.5775318077462203 2.0949379676602016
        children [
          DEF POLE_ENDPOINT_2 Solid {
            translation 0.5000000000000002 0 0
            children [
              DEF BALL Shape {
                appearance PBRAppearance {
                  baseColor 0.03137254901960784 0.047058823529411764 1
                  metalness 0
                }
                geometry Sphere {
                  radius 0.01
                }
              }
            ]
            boundingObject USE BALL
            physics Physics {
              density -1
              mass 0.02
            }
          }
          DEF POLE Shape {
            appearance PBRAppearance {
              baseColor 1 0.1568627450980392 0.1568627450980392
              roughness 1
              metalness 0
            }
            geometry Box {
              size 1 0.020000000000000004 0.019999999999999997
            }
          }
          DEF CONNECTOR_HINGE HingeJoint {
            jointParameters HingeJointParameters {
              axis 0 1 0
              anchor 0.4925 0 0.0099993
            }
            endPoint DEF CONNECTION_POLE Solid {
              translation 0.49250000000000005 0 0.0910000000000004
              rotation 0 1 0 1.5707999999999942
              children [
                DEF CONNECTIONG_POLE Shape {
                  appearance PBRAppearance {
                    baseColor 1 0.1568627450980392 0.1568627450980392
                    roughness 1
                    metalness 0
                  }
                  geometry Box {
                    size 0.17 0.02 0.02
                  }
                }
                Connector {
                  translation -0.085 0 0
                  rotation 0 1 0 3.14159
                  isLocked TRUE
                  autoLock TRUE
                }
              ]
              name "solid(4)"
              boundingObject USE CONNECTIONG_POLE
              physics Physics {
              }
            }
          }
        ]
        name "pole"
        boundingObject USE POLE
        physics Physics {
          density -1
          mass 0.2
        }
      }
    }
  ]
  name "robot2"
  boundingObject USE BODY
  physics Physics {
    density -1
    mass 2
  }
  controller "robot_controller"
  supervisor TRUE
}
Robot {
  children [
    Receiver {
      name "receiver1"
      channel 2
    }
    Emitter {
      name "emitter1"
      channel 2
    }
    Emitter {
      name "emitter0"
      channel 1
    }
    Receiver {
      name "receiver0"
      channel 1
    }
  ]
  controller "supervisor_manager"
  supervisor TRUE
}
